Workbook

Sheet INICIO
B2: SISTEMA DE SEGUIMIENTO DE ESTUDIANTES
B4: Mentoría Pedagógica — Matriz de Análisis de Datos
B6: INTERPRETACIÓN DEL SEMÁFORO
B7: 🟢 VERDE — 0 a 2 pts | C7: Seguimiento Universal Conversaciones preventivas · Reconocimiento de fortalezas · Seguimiento mensual
B8: 🟡 AMARILLO — 3 a 5 pts | C8: Seguimiento Focalizado Reunión mentor-estudiante · Registro de evidencias · Acuerdos de mejora · Seguimiento quincenal · Contacto preventivo con familia
B9: 🔴 ROJO — 6 a 12 pts | C9: Seguimiento Intensivo Plan de acompañamiento · Reunión con familia · Derivación · Coordinación con convivencia/orientación/PIE · Seguimiento semanal
B11: CRITERIOS DE OBSERVACIÓN (0–3 por ámbito)
B12: TRAYECTORIA EDUCATIVA | C12: ÁMBITO ACADÉMICO | D12: ÁMBITO CONDUCTUAL
B13: 0 - Trayectoria regular | C13: 0 - Sin alertas académicas | D13: 0 - Sin observaciones conductuales
B14: 1 - Alertas leves o puntuales | C14: 1 - Descenso leve o puntual | D14: 1 - Conductas ocasionales
B15: 2 - Dificultades reiteradas | C15: 2 - Descenso sostenido / varias asignaturas | D15: 2 - Conductas reiteradas
B16: 3 - Riesgo alto de deserción | C16: 3 - Riesgo académico significativo | D16: 3 - Conductas frecuentes / afectan convivencia
B17: ÁMBITO SOCIOEMOCIONAL | C17: INSTRUCCIONES DE USO
B18: 0 - Ajuste adecuado | C18: 1. Ir a la hoja del curso correspondiente (ej: KB, 1A, 3mB...)
B19: 1 - Señales leves de preocupación | C19: 2. Ingresar nombre del estudiante y mentor en las columnas B y C
B20: 2 - Dificultades persistentes | C20: 3. Seleccionar el puntaje de cada ámbito con el menú desplegable
B21: 3 - Alta vulnerabilidad o riesgo | C21: 4. El Total y Semáforo se calculan automáticamente
C22: 5. Ver hoja RESUMEN para estadísticas de todos los cursos
C23: 6. Ver hoja BÚSQUEDA para filtrar estudiantes por criterios

Sheet PKA
A1: CURSO PKA — Registro de Seguimiento de Estudiantes
A2: PUNTAJES: 0 = Sin alerta / Regular 1 = Alerta leve 2 = Alerta moderada / Reiterada 3 = Alto riesgo │ SEMÁFORO: Verde 0-2 · Amarillo 3-5 · Rojo 6-12
D3: PUNTAJES POR ÁMBITO (seleccionar del menú desplegable) | H3: RESULTADO
A4: N° | B4: NOMBRE ESTUDIANTE | C4: MENTOR RESPONSABLE | D4: TRAYECTORIA EDUCATIVA | E4: ÁMBITO ACADÉMICO | F4: ÁMBITO CONDUCTUAL | G4: ÁMBITO SOCIOEMOCIONAL | H4: TOTAL | I4: SEMÁFORO | J4: OBSERVACIONES / NOTAS
A5: =IF(B5<>"",ROW()-4,"") | H5: =IF(B5="","",IFERROR(IF(D5="",0,VALUE(LEFT(D5,1)))+IF(E5="",0,VALUE(LEFT(E5,1)))+IF(F5="",0,VALUE(LEFT(F5,1)))+IF(G5="",0,VALUE(LEFT(G5,1))),0)) | I5: =IF(B5="","",IF(H5<=2,"🟢 VERDE",IF(H5<=5,"🟡 AMARILLO","🔴 ROJO")))
A6: =IF(B6<>"",ROW()-4,"") | H6: =IF(B6="","",IFERROR(IF(D6="",0,VALUE(LEFT(D6,1)))+IF(E6="",0,VALUE(LEFT(E6,1)))+IF(F6="",0,VALUE(LEFT(F6,1)))+IF(G6="",0,VALUE(LEFT(G6,1))),0)) | I6: =IF(B6="","",IF(H6<=2,"🟢 VERDE",IF(H6<=5,"🟡 AMARILLO","🔴 ROJO")))
A7: =IF(B7<>"",ROW()-4,"") | H7: =IF(B7="","",IFERROR(IF(D7="",0,VALUE(LEFT(D7,1)))+IF(E7="",0,VALUE(LEFT(E7,1)))+IF(F7="",0,VALUE(LEFT(F7,1)))+IF(G7="",0,VALUE(LEFT(G7,1))),0)) | I7: =IF(B7="","",IF(H7<=2,"🟢 VERDE",IF(H7<=5,"🟡 AMARILLO","🔴 ROJO")))
A8: =IF(B8<>"",ROW()-4,"") | H8: =IF(B8="","",IFERROR(IF(D8="",0,VALUE(LEFT(D8,1)))+IF(E8="",0,VALUE(LEFT(E8,1)))+IF(F8="",0,VALUE(LEFT(F8,1)))+IF(G8="",0,VALUE(LEFT(G8,1))),0)) | I8: =IF(B8="","",IF(H8<=2,"🟢 VERDE",IF(H8<=5,"🟡 AMARILLO","🔴 ROJO")))
A9: =IF(B9<>"",ROW()-4,"") | H9: =IF(B9="","",IFERROR(IF(D9="",0,VALUE(LEFT(D9,1)))+IF(E9="",0,VALUE(LEFT(E9,1)))+IF(F9="",0,VALUE(LEFT(F9,1)))+IF(G9="",0,VALUE(LEFT(G9,1))),0)) | I9: =IF(B9="","",IF(H9<=2,"🟢 VERDE",IF(H9<=5,"🟡 AMARILLO","🔴 ROJO")))
A10: =IF(B10<>"",ROW()-4,"") | H10: =IF(B10="","",IFERROR(IF(D10="",0,VALUE(LEFT(D10,1)))+IF(E10="",0,VALUE(LEFT(E10,1)))+IF(F10="",0,VALUE(LEFT(F10,1)))+IF(G10="",0,VALUE(LEFT(G10,1))),0)) | I10: =IF(B10="","",IF(H10<=2,"🟢 VERDE",IF(H10<=5,"🟡 AMARILLO","🔴 ROJO")))
A11: =IF(B11<>"",ROW()-4,"") | H11: =IF(B11="","",IFERROR(IF(D11="",0,VALUE(LEFT(D11,1)))+IF(E11="",0,VALUE(LEFT(E11,1)))+IF(F11="",0,VALUE(LEFT(F11,1)))+IF(G11="",0,VALUE(LEFT(G11,1))),0)) | I11: =IF(B11="","",IF(H11<=2,"🟢 VERDE",IF(H11<=5,"🟡 AMARILLO","🔴 ROJO")))
A12: =IF(B12<>"",ROW()-4,"") | H12: =IF(B12="","",IFERROR(IF(D12="",0,VALUE(LEFT(D12,1)))+IF(E12="",0,VALUE(LEFT(E12,1)))+IF(F12="",0,VALUE(LEFT(F12,1)))+IF(G12="",0,VALUE(LEFT(G12,1))),0)) | I12: =IF(B12="","",IF(H12<=2,"🟢 VERDE",IF(H12<=5,"🟡 AMARILLO","🔴 ROJO")))
A13: =IF(B13<>"",ROW()-4,"") | H13: =IF(B13="","",IFERROR(IF(D13="",0,VALUE(LEFT(D13,1)))+IF(E13="",0,VALUE(LEFT(E13,1)))+IF(F13="",0,VALUE(LEFT(F13,1)))+IF(G13="",0,VALUE(LEFT(G13,1))),0)) | I13: =IF(B13="","",IF(H13<=2,"🟢 VERDE",IF(H13<=5,"🟡 AMARILLO","🔴 ROJO")))
A14: =IF(B14<>"",ROW()-4,"") | H14: =IF(B14="","",IFERROR(IF(D14="",0,VALUE(LEFT(D14,1)))+IF(E14="",0,VALUE(LEFT(E14,1)))+IF(F14="",0,VALUE(LEFT(F14,1)))+IF(G14="",0,VALUE(LEFT(G14,1))),0)) | I14: =IF(B14="","",IF(H14<=2,"🟢 VERDE",IF(H14<=5,"🟡 AMARILLO","🔴 ROJO")))
A15: =IF(B15<>"",ROW()-4,"") | H15: =IF(B15="","",IFERROR(IF(D15="",0,VALUE(LEFT(D15,1)))+IF(E15="",0,VALUE(LEFT(E15,1)))+IF(F15="",0,VALUE(LEFT(F15,1)))+IF(G15="",0,VALUE(LEFT(G15,1))),0)) | I15: =IF(B15="","",IF(H15<=2,"🟢 VERDE",IF(H15<=5,"🟡 AMARILLO","🔴 ROJO")))
A16: =IF(B16<>"",ROW()-4,"") | H16: =IF(B16="","",IFERROR(IF(D16="",0,VALUE(LEFT(D16,1)))+IF(E16="",0,VALUE(LEFT(E16,1)))+IF(F16="",0,VALUE(LEFT(F16,1)))+IF(G16="",0,VALUE(LEFT(G16,1))),0)) | I16: =IF(B16="","",IF(H16<=2,"🟢 VERDE",IF(H16<=5,"🟡 AMARILLO","🔴 ROJO")))
... A54: =IF(B54<>"",ROW()-4,"") | H54: =IF(B54="","",IFERROR(IF(D54="",0,VALUE(LEFT(D54,1)))+IF(E54="",0,VALUE(LEFT(E54,1)))+IF(F54="",0,VALUE(LEFT(F54,1)))+IF(G54="",0,VALUE(LEFT(G54,1))),0)) | I54: =IF(B54="","",IF(H54<=2,"🟢 VERDE",IF(H54<=5,"🟡 AMARILLO","🔴 ROJO")))
A55: TOTALES CURSO PKA | D55: =COUNTIF(D5:D54,"<>"&"") | E55: =COUNTIF(E5:E54,"<>"&"") | F55: =COUNTIF(F5:F54,"<>"&"") | G55: =COUNTIF(G5:G54,"<>"&"") | H55: =COUNTA(B5:B54) | I55: =COUNTIF(I5:I54,"🔴 ROJO")&" 🔴 "&COUNTIF(I5:I54,"🟡 AMARILLO")&" 🟡 "&COUNTIF(I5:I54,"🟢 VERDE")&" 🟢" | J55: ← Conteo: Rojo · Amarillo · Verde

Sheet PKB
A1: CURSO PKB — Registro de Seguimiento de Estudiantes
A2: PUNTAJES: 0 = Sin alerta / Regular 1 = Alerta leve 2 = Alerta moderada / Reiterada 3 = Alto riesgo │ SEMÁFORO: Verde 0-2 · Amarillo 3-5 · Rojo 6-12
D3: PUNTAJES POR ÁMBITO (seleccionar del menú desplegable) | H3: RESULTADO
A4: N° | B4: NOMBRE ESTUDIANTE | C4: MENTOR RESPONSABLE | D4: TRAYECTORIA EDUCATIVA | E4: ÁMBITO ACADÉMICO | F4: ÁMBITO CONDUCTUAL | G4: ÁMBITO SOCIOEMOCIONAL | H4: TOTAL | I4: SEMÁFORO | J4: OBSERVACIONES / NOTAS
A5: =IF(B5<>"",ROW()-4,"") | H5: =IF(B5="","",IFERROR(IF(D5="",0,VALUE(LEFT(D5,1)))+IF(E5="",0,VALUE(LEFT(E5,1)))+IF(F5="",0,VALUE(LEFT(F5,1)))+IF(G5="",0,VALUE(LEFT(G5,1))),0)) | I5: =IF(B5="","",IF(H5<=2,"🟢 VERDE",IF(H5<=5,"🟡 AMARILLO","🔴 ROJO")))
A6: =IF(B6<>"",ROW()-4,"") | H6: =IF(B6="","",IFERROR(IF(D6="",0,VALUE(LEFT(D6,1)))+IF(E6="",0,VALUE(LEFT(E6,1)))+IF(F6="",0,VALUE(LEFT(F6,1)))+IF(G6="",0,VALUE(LEFT(G6,1))),0)) | I6: =IF(B6="","",IF(H6<=2,"🟢 VERDE",IF(H6<=5,"🟡 AMARILLO","🔴 ROJO")))
A7: =IF(B7<>"",ROW()-4,"") | H7: =IF(B7="","",IFERROR(IF(D7="",0,VALUE(LEFT(D7,1)))+IF(E7="",0,VALUE(LEFT(E7,1)))+IF(F7="",0,VALUE(LEFT(F7,1)))+IF(G7="",0,VALUE(LEFT(G7,1))),0)) | I7: =IF(B7="","",IF(H7<=2,"🟢 VERDE",IF(H7<=5,"🟡 AMARILLO","🔴 ROJO")))
A8: =IF(B8<>"",ROW()-4,"") | H8: =IF(B8="","",IFERROR(IF(D8="",0,VALUE(LEFT(D8,1)))+IF(E8="",0,VALUE(LEFT(E8,1)))+IF(F8="",0,VALUE(LEFT(F8,1)))+IF(G8="",0,VALUE(LEFT(G8,1))),0)) | I8: =IF(B8="","",IF(H8<=2,"🟢 VERDE",IF(H8<=5,"🟡 AMARILLO","🔴 ROJO")))
A9: =IF(B9<>"",ROW()-4,"") | H9: =IF(B9="","",IFERROR(IF(D9="",0,VALUE(LEFT(D9,1)))+IF(E9="",0,VALUE(LEFT(E9,1)))+IF(F9="",0,VALUE(LEFT(F9,1)))+IF(G9="",0,VALUE(LEFT(G9,1))),0)) | I9: =IF(B9="","",IF(H9<=2,"🟢 VERDE",IF(H9<=5,"🟡 AMARILLO","🔴 ROJO")))
A10: =IF(B10<>"",ROW()-4,"") | H10: =IF(B10="","",IFERROR(IF(D10="",0,VALUE(LEFT(D10,1)))+IF(E10="",0,VALUE(LEFT(E10,1)))+IF(F10="",0,VALUE(LEFT(F10,1)))+IF(G10="",0,VALUE(LEFT(G10,1))),0)) | I10: =IF(B10="","",IF(H10<=2,"🟢 VERDE",IF(H10<=5,"🟡 AMARILLO","🔴 ROJO")))
A11: =IF(B11<>"",ROW()-4,"") | H11: =IF(B11="","",IFERROR(IF(D11="",0,VALUE(LEFT(D11,1)))+IF(E11="",0,VALUE(LEFT(E11,1)))+IF(F11="",0,VALUE(LEFT(F11,1)))+IF(G11="",0,VALUE(LEFT(G11,1))),0)) | I11: =IF(B11="","",IF(H11<=2,"🟢 VERDE",IF(H11<=5,"🟡 AMARILLO","🔴 ROJO")))
A12: =IF(B12<>"",ROW()-4,"") | H12: =IF(B12="","",IFERROR(IF(D12="",0,VALUE(LEFT(D12,1)))+IF(E12="",0,VALUE(LEFT(E12,1)))+IF(F12="",0,VALUE(LEFT(F12,1)))+IF(G12="",0,VALUE(LEFT(G12,1))),0)) | I12: =IF(B12="","",IF(H12<=2,"🟢 VERDE",IF(H12<=5,"🟡 AMARILLO","🔴 ROJO")))
A13: =IF(B13<>"",ROW()-4,"") | H13: =IF(B13="","",IFERROR(IF(D13="",0,VALUE(LEFT(D13,1)))+IF(E13="",0,VALUE(LEFT(E13,1)))+IF(F13="",0,VALUE(LEFT(F13,1)))+IF(G13="",0,VALUE(LEFT(G13,1))),0)) | I13: =IF(B13="","",IF(H13<=2,"🟢 VERDE",IF(H13<=5,"🟡 AMARILLO","🔴 ROJO")))
A14: =IF(B14<>"",ROW()-4,"") | H14: =IF(B14="","",IFERROR(IF(D14="",0,VALUE(LEFT(D14,1)))+IF(E14="",0,VALUE(LEFT(E14,1)))+IF(F14="",0,VALUE(LEFT(F14,1)))+IF(G14="",0,VALUE(LEFT(G14,1))),0)) | I14: =IF(B14="","",IF(H14<=2,"🟢 VERDE",IF(H14<=5,"🟡 AMARILLO","🔴 ROJO")))
A15: =IF(B15<>"",ROW()-4,"") | H15: =IF(B15="","",IFERROR(IF(D15="",0,VALUE(LEFT(D15,1)))+IF(E15="",0,VALUE(LEFT(E15,1)))+IF(F15="",0,VALUE(LEFT(F15,1)))+IF(G15="",0,VALUE(LEFT(G15,1))),0)) | I15: =IF(B15="","",IF(H15<=2,"🟢 VERDE",IF(H15<=5,"🟡 AMARILLO","🔴 ROJO")))
A16: =IF(B16<>"",ROW()-4,"") | H16: =IF(B16="","",IFERROR(IF(D16="",0,VALUE(LEFT(D16,1)))+IF(E16="",0,VALUE(LEFT(E16,1)))+IF(F16="",0,VALUE(LEFT(F16,1)))+IF(G16="",0,VALUE(LEFT(G16,1))),0)) | I16: =IF(B16="","",IF(H16<=2,"🟢 VERDE",IF(H16<=5,"🟡 AMARILLO","🔴 ROJO")))
... A54: =IF(B54<>"",ROW()-4,"") | H54: =IF(B54="","",IFERROR(IF(D54="",0,VALUE(LEFT(D54,1)))+IF(E54="",0,VALUE(LEFT(E54,1)))+IF(F54="",0,VALUE(LEFT(F54,1)))+IF(G54="",0,VALUE(LEFT(G54,1))),0)) | I54: =IF(B54="","",IF(H54<=2,"🟢 VERDE",IF(H54<=5,"🟡 AMARILLO","🔴 ROJO")))
A55: TOTALES CURSO PKB | D55: =COUNTIF(D5:D54,"<>"&"") | E55: =COUNTIF(E5:E54,"<>"&"") | F55: =COUNTIF(F5:F54,"<>"&"") | G55: =COUNTIF(G5:G54,"<>"&"") | H55: =COUNTA(B5:B54) | I55: =COUNTIF(I5:I54,"🔴 ROJO")&" 🔴 "&COUNTIF(I5:I54,"🟡 AMARILLO")&" 🟡 "&COUNTIF(I5:I54,"🟢 VERDE")&" 🟢" | J55: ← Conteo: Rojo · Amarillo · Verde

Sheet PKC
A1: CURSO PKC — Registro de Seguimiento de Estudiantes
A2: PUNTAJES: 0 = Sin alerta / Regular 1 = Alerta leve 2 = Alerta moderada / Reiterada 3 = Alto riesgo │ SEMÁFORO: Verde 0-2 · Amarillo 3-5 · Rojo 6-12
D3: PUNTAJES POR ÁMBITO (seleccionar del menú desplegable) | H3: RESULTADO
A4: N° | B4: NOMBRE ESTUDIANTE | C4: MENTOR RESPONSABLE | D4: TRAYECTORIA EDUCATIVA | E4: ÁMBITO ACADÉMICO | F4: ÁMBITO CONDUCTUAL | G4: ÁMBITO SOCIOEMOCIONAL | H4: TOTAL | I4: SEMÁFORO | J4: OBSERVACIONES / NOTAS
A5: =IF(B5<>"",ROW()-4,"") | H5: =IF(B5="","",IFERROR(IF(D5="",0,VALUE(LEFT(D5,1)))+IF(E5="",0,VALUE(LEFT(E5,1)))+IF(F5="",0,VALUE(LEFT(F5,1)))+IF(G5="",0,VALUE(LEFT(G5,1))),0)) | I5: =IF(B5="","",IF(H5<=2,"🟢 VERDE",IF(H5<=5,"🟡 AMARILLO","🔴 ROJO")))
A6: =IF(B6<>"",ROW()-4,"") | H6: =IF(B6="","",IFERROR(IF(D6="",0,VALUE(LEFT(D6,1)))+IF(E6="",0,VALUE(LEFT(E6,1)))+IF(F6="",0,VALUE(LEFT(F6,1)))+IF(G6="",0,VALUE(LEFT(G6,1))),0)) | I6: =IF(B6="","",IF(H6<=2,"🟢 VERDE",IF(H6<=5,"🟡 AMARILLO","🔴 ROJO")))
A7: =IF(B7<>"",ROW()-4,"") | H7: =IF(B7="","",IFERROR(IF(D7="",0,VALUE(LEFT(D7,1)))+IF(E7="",0,VALUE(LEFT(E7,1)))+IF(F7="",0,VALUE(LEFT(F7,1)))+IF(G7="",0,VALUE(LEFT(G7,1))),0)) | I7: =IF(B7="","",IF(H7<=2,"🟢 VERDE",IF(H7<=5,"🟡 AMARILLO","🔴 ROJO")))
A8: =IF(B8<>"",ROW()-4,"") | H8: =IF(B8="","",IFERROR(IF(D8="",0,VALUE(LEFT(D8,1)))+IF(E8="",0,VALUE(LEFT(E8,1)))+IF(F8="",0,VALUE(LEFT(F8,1)))+IF(G8="",0,VALUE(LEFT(G8,1))),0)) | I8: =IF(B8="","",IF(H8<=2,"🟢 VERDE",IF(H8<=5,"🟡 AMARILLO","🔴 ROJO")))
A9: =IF(B9<>"",ROW()-4,"") | H9: =IF(B9="","",IFERROR(IF(D9="",0,VALUE(LEFT(D9,1)))+IF(E9="",0,VALUE(LEFT(E9,1)))+IF(F9="",0,VALUE(LEFT(F9,1)))+IF(G9="",0,VALUE(LEFT(G9,1))),0)) | I9: =IF(B9="","",IF(H9<=2,"🟢 VERDE",IF(H9<=5,"🟡 AMARILLO","🔴 ROJO")))
A10: =IF(B10<>"",ROW()-4,"") | H10: =IF(B10="","",IFERROR(IF(D10="",0,VALUE(LEFT(D10,1)))+IF(E10="",0,VALUE(LEFT(E10,1)))+IF(F10="",0,VALUE(LEFT(F10,1)))+IF(G10="",0,VALUE(LEFT(G10,1))),0)) | I10: =IF(B10="","",IF(H10<=2,"🟢 VERDE",IF(H10<=5,"🟡 AMARILLO","🔴 ROJO")))
A11: =IF(B11<>"",ROW()-4,"") | H11: =IF(B11="","",IFERROR(IF(D11="",0,VALUE(LEFT(D11,1)))+IF(E11="",0,VALUE(LEFT(E11,1)))+IF(F11="",0,VALUE(LEFT(F11,1)))+IF(G11="",0,VALUE(LEFT(G11,1))),0)) | I11: =IF(B11="","",IF(H11<=2,"🟢 VERDE",IF(H11<=5,"🟡 AMARILLO","🔴 ROJO")))
A12: =IF(B12<>"",ROW()-4,"") | H12: =IF(B12="","",IFERROR(IF(D12="",0,VALUE(LEFT(D12,1)))+IF(E12="",0,VALUE(LEFT(E12,1)))+IF(F12="",0,VALUE(LEFT(F12,1)))+IF(G12="",0,VALUE(LEFT(G12,1))),0)) | I12: =IF(B12="","",IF(H12<=2,"🟢 VERDE",IF(H12<=5,"🟡 AMARILLO","🔴 ROJO")))
A13: =IF(B13<>"",ROW()-4,"") | H13: =IF(B13="","",IFERROR(IF(D13="",0,VALUE(LEFT(D13,1)))+IF(E13="",0,VALUE(LEFT(E13,1)))+IF(F13="",0,VALUE(LEFT(F13,1)))+IF(G13="",0,VALUE(LEFT(G13,1))),0)) | I13: =IF(B13="","",IF(H13<=2,"🟢 VERDE",IF(H13<=5,"🟡 AMARILLO","🔴 ROJO")))
A14: =IF(B14<>"",ROW()-4,"") | H14: =IF(B14="","",IFERROR(IF(D14="",0,VALUE(LEFT(D14,1)))+IF(E14="",0,VALUE(LEFT(E14,1)))+IF(F14="",0,VALUE(LEFT(F14,1)))+IF(G14="",0,VALUE(LEFT(G14,1))),0)) | I14: =IF(B14="","",IF(H14<=2,"🟢 VERDE",IF(H14<=5,"🟡 AMARILLO","🔴 ROJO")))
A15: =IF(B15<>"",ROW()-4,"") | H15: =IF(B15="","",IFERROR(IF(D15="",0,VALUE(LEFT(D15,1)))+IF(E15="",0,VALUE(LEFT(E15,1)))+IF(F15="",0,VALUE(LEFT(F15,1)))+IF(G15="",0,VALUE(LEFT(G15,1))),0)) | I15: =IF(B15="","",IF(H15<=2,"🟢 VERDE",IF(H15<=5,"🟡 AMARILLO","🔴 ROJO")))
A16: =IF(B16<>"",ROW()-4,"") | H16: =IF(B16="","",IFERROR(IF(D16="",0,VALUE(LEFT(D16,1)))+IF(E16="",0,VALUE(LEFT(E16,1)))+IF(F16="",0,VALUE(LEFT(F16,1)))+IF(G16="",0,VALUE(LEFT(G16,1))),0)) | I16: =IF(B16="","",IF(H16<=2,"🟢 VERDE",IF(H16<=5,"🟡 AMARILLO","🔴 ROJO")))
... A54: =IF(B54<>"",ROW()-4,"") | H54: =IF(B54="","",IFERROR(IF(D54="",0,VALUE(LEFT(D54,1)))+IF(E54="",0,VALUE(LEFT(E54,1)))+IF(F54="",0,VALUE(LEFT(F54,1)))+IF(G54="",0,VALUE(LEFT(G54,1))),0)) | I54: =IF(B54="","",IF(H54<=2,"🟢 VERDE",IF(H54<=5,"🟡 AMARILLO","🔴 ROJO")))
A55: TOTALES CURSO PKC | D55: =COUNTIF(D5:D54,"<>"&"") | E55: =COUNTIF(E5:E54,"<>"&"") | F55: =COUNTIF(F5:F54,"<>"&"") | G55: =COUNTIF(G5:G54,"<>"&"") | H55: =COUNTA(B5:B54) | I55: =COUNTIF(I5:I54,"🔴 ROJO")&" 🔴 "&COUNTIF(I5:I54,"🟡 AMARILLO")&" 🟡 "&COUNTIF(I5:I54,"🟢 VERDE")&" 🟢" | J55: ← Conteo: Rojo · Amarillo · Verde

Sheet KA
A1: CURSO KA — Registro de Seguimiento de Estudiantes
A2: PUNTAJES: 0 = Sin alerta / Regular 1 = Alerta leve 2 = Alerta moderada / Reiterada 3 = Alto riesgo │ SEMÁFORO: Verde 0-2 · Amarillo 3-5 · Rojo 6-12
D3: PUNTAJES POR ÁMBITO (seleccionar del menú desplegable) | H3: RESULTADO
A4: N° | B4: NOMBRE ESTUDIANTE | C4: MENTOR RESPONSABLE | D4: TRAYECTORIA EDUCATIVA | E4: ÁMBITO ACADÉMICO | F4: ÁMBITO CONDUCTUAL | G4: ÁMBITO SOCIOEMOCIONAL | H4: TOTAL | I4: SEMÁFORO | J4: OBSERVACIONES / NOTAS
A5: =IF(B5<>"",ROW()-4,"") | H5: =IF(B5="","",IFERROR(IF(D5="",0,VALUE(LEFT(D5,1)))+IF(E5="",0,VALUE(LEFT(E5,1)))+IF(F5="",0,VALUE(LEFT(F5,1)))+IF(G5="",0,VALUE(LEFT(G5,1))),0)) | I5: =IF(B5="","",IF(H5<=2,"🟢 VERDE",IF(H5<=5,"🟡 AMARILLO","🔴 ROJO")))
A6: =IF(B6<>"",ROW()-4,"") | H6: =IF(B6="","",IFERROR(IF(D6="",0,VALUE(LEFT(D6,1)))+IF(E6="",0,VALUE(LEFT(E6,1)))+IF(F6="",0,VALUE(LEFT(F6,1)))+IF(G6="",0,VALUE(LEFT(G6,1))),0)) | I6: =IF(B6="","",IF(H6<=2,"🟢 VERDE",IF(H6<=5,"🟡 AMARILLO","🔴 ROJO")))
A7: =IF(B7<>"",ROW()-4,"") | H7: =IF(B7="","",IFERROR(IF(D7="",0,VALUE(LEFT(D7,1)))+IF(E7="",0,VALUE(LEFT(E7,1)))+IF(F7="",0,VALUE(LEFT(F7,1)))+IF(G7="",0,VALUE(LEFT(G7,1))),0)) | I7: =IF(B7="","",IF(H7<=2,"🟢 VERDE",IF(H7<=5,"🟡 AMARILLO","🔴 ROJO")))
A8: =IF(B8<>"",ROW()-4,"") | H8: =IF(B8="","",IFERROR(IF(D8="",0,VALUE(LEFT(D8,1)))+IF(E8="",0,VALUE(LEFT(E8,1)))+IF(F8="",0,VALUE(LEFT(F8,1)))+IF(G8="",0,VALUE(LEFT(G8,1))),0)) | I8: =IF(B8="","",IF(H8<=2,"🟢 VERDE",IF(H8<=5,"🟡 AMARILLO","🔴 ROJO")))
A9: =IF(B9<>"",ROW()-4,"") | H9: =IF(B9="","",IFERROR(IF(D9="",0,VALUE(LEFT(D9,1)))+IF(E9="",0,VALUE(LEFT(E9,1)))+IF(F9="",0,VALUE(LEFT(F9,1)))+IF(G9="",0,VALUE(LEFT(G9,1))),0)) | I9: =IF(B9="","",IF(H9<=2,"🟢 VERDE",IF(H9<=5,"🟡 AMARILLO","🔴 ROJO")))
A10: =IF(B10<>"",ROW()-4,"") | H10: =IF(B10="","",IFERROR(IF(D10="",0,VALUE(LEFT(D10,1)))+IF(E10="",0,VALUE(LEFT(E10,1)))+IF(F10="",0,VALUE(LEFT(F10,1)))+IF(G10="",0,VALUE(LEFT(G10,1))),0)) | I10: =IF(B10="","",IF(H10<=2,"🟢 VERDE",IF(H10<=5,"🟡 AMARILLO","🔴 ROJO")))
A11: =IF(B11<>"",ROW()-4,"") | H11: =IF(B11="","",IFERROR(IF(D11="",0,VALUE(LEFT(D11,1)))+IF(E11="",0,VALUE(LEFT(E11,1)))+IF(F11="",0,VALUE(LEFT(F11,1)))+IF(G11="",0,VALUE(LEFT(G11,1))),0)) | I11: =IF(B11="","",IF(H11<=2,"🟢 VERDE",IF(H11<=5,"🟡 AMARILLO","🔴 ROJO")))
A12: =IF(B12<>"",ROW()-4,"") | H12: =IF(B12="","",IFERROR(IF(D12="",0,VALUE(LEFT(D12,1)))+IF(E12="",0,VALUE(LEFT(E12,1)))+IF(F12="",0,VALUE(LEFT(F12,1)))+IF(G12="",0,VALUE(LEFT(G12,1))),0)) | I12: =IF(B12="","",IF(H12<=2,"🟢 VERDE",IF(H12<=5,"🟡 AMARILLO","🔴 ROJO")))
A13: =IF(B13<>"",ROW()-4,"") | H13: =IF(B13="","",IFERROR(IF(D13="",0,VALUE(LEFT(D13,1)))+IF(E13="",0,VALUE(LEFT(E13,1)))+IF(F13="",0,VALUE(LEFT(F13,1)))+IF(G13="",0,VALUE(LEFT(G13,1))),0)) | I13: =IF(B13="","",IF(H13<=2,"🟢 VERDE",IF(H13<=5,"🟡 AMARILLO","🔴 ROJO")))
A14: =IF(B14<>"",ROW()-4,"") | H14: =IF(B14="","",IFERROR(IF(D14="",0,VALUE(LEFT(D14,1)))+IF(E14="",0,VALUE(LEFT(E14,1)))+IF(F14="",0,VALUE(LEFT(F14,1)))+IF(G14="",0,VALUE(LEFT(G14,1))),0)) | I14: =IF(B14="","",IF(H14<=2,"🟢 VERDE",IF(H14<=5,"🟡 AMARILLO","🔴 ROJO")))
A15: =IF(B15<>"",ROW()-4,"") | H15: =IF(B15="","",IFERROR(IF(D15="",0,VALUE(LEFT(D15,1)))+IF(E15="",0,VALUE(LEFT(E15,1)))+IF(F15="",0,VALUE(LEFT(F15,1)))+IF(G15="",0,VALUE(LEFT(G15,1))),0)) | I15: =IF(B15="","",IF(H15<=2,"🟢 VERDE",IF(H15<=5,"🟡 AMARILLO","🔴 ROJO")))
A16: =IF(B16<>"",ROW()-4,"") | H16: =IF(B16="","",IFERROR(IF(D16="",0,VALUE(LEFT(D16,1)))+IF(E16="",0,VALUE(LEFT(E16,1)))+IF(F16="",0,VALUE(LEFT(F16,1)))+IF(G16="",0,VALUE(LEFT(G16,1))),0)) | I16: =IF(B16="","",IF(H16<=2,"🟢 VERDE",IF(H16<=5,"🟡 AMARILLO","🔴 ROJO")))
... A54: =IF(B54<>"",ROW()-4,"") | H54: =IF(B54="","",IFERROR(IF(D54="",0,VALUE(LEFT(D54,1)))+IF(E54="",0,VALUE(LEFT(E54,1)))+IF(F54="",0,VALUE(LEFT(F54,1)))+IF(G54="",0,VALUE(LEFT(G54,1))),0)) | I54: =IF(B54="","",IF(H54<=2,"🟢 VERDE",IF(H54<=5,"🟡 AMARILLO","🔴 ROJO")))
A55: TOTALES CURSO KA | D55: =COUNTIF(D5:D54,"<>"&"") | E55: =COUNTIF(E5:E54,"<>"&"") | F55: =COUNTIF(F5:F54,"<>"&"") | G55: =COUNTIF(G5:G54,"<>"&"") | H55: =COUNTA(B5:B54) | I55: =COUNTIF(I5:I54,"🔴 ROJO")&" 🔴 "&COUNTIF(I5:I54,"🟡 AMARILLO")&" 🟡 "&COUNTIF(I5:I54,"🟢 VERDE")&" 🟢" | J55: ← Conteo: Rojo · Amarillo · Verde

Sheet KB
A1: CURSO KB — Registro de Seguimiento de Estudiantes
A2: PUNTAJES: 0 = Sin alerta / Regular 1 = Alerta leve 2 = Alerta moderada / Reiterada 3 = Alto riesgo │ SEMÁFORO: Verde 0-2 · Amarillo 3-5 · Rojo 6-12
D3: PUNTAJES POR ÁMBITO (seleccionar del menú desplegable) | H3: RESULTADO
A4: N° | B4: NOMBRE ESTUDIANTE | C4: MENTOR RESPONSABLE | D4: TRAYECTORIA EDUCATIVA | E4: ÁMBITO ACADÉMICO | F4: ÁMBITO CONDUCTUAL | G4: ÁMBITO SOCIOEMOCIONAL | H4: TOTAL | I4: SEMÁFORO | J4: OBSERVACIONES / NOTAS
A5: =IF(B5<>"",ROW()-4,"") | H5: =IF(B5="","",IFERROR(IF(D5="",0,VALUE(LEFT(D5,1)))+IF(E5="",0,VALUE(LEFT(E5,1)))+IF(F5="",0,VALUE(LEFT(F5,1)))+IF(G5="",0,VALUE(LEFT(G5,1))),0)) | I5: =IF(B5="","",IF(H5<=2,"🟢 VERDE",IF(H5<=5,"🟡 AMARILLO","🔴 ROJO")))
A6: =IF(B6<>"",ROW()-4,"") | H6: =IF(B6="","",IFERROR(IF(D6="",0,VALUE(LEFT(D6,1)))+IF(E6="",0,VALUE(LEFT(E6,1)))+IF(F6="",0,VALUE(LEFT(F6,1)))+IF(G6="",0,VALUE(LEFT(G6,1))),0)) | I6: =IF(B6="","",IF(H6<=2,"🟢 VERDE",IF(H6<=5,"🟡 AMARILLO","🔴 ROJO")))
A7: =IF(B7<>"",ROW()-4,"") | H7: =IF(B7="","",IFERROR(IF(D7="",0,VALUE(LEFT(D7,1)))+IF(E7="",0,VALUE(LEFT(E7,1)))+IF(F7="",0,VALUE(LEFT(F7,1)))+IF(G7="",0,VALUE(LEFT(G7,1))),0)) | I7: =IF(B7="","",IF(H7<=2,"🟢 VERDE",IF(H7<=5,"🟡 AMARILLO","🔴 ROJO")))
A8: =IF(B8<>"",ROW()-4,"") | H8: =IF(B8="","",IFERROR(IF(D8="",0,VALUE(LEFT(D8,1)))+IF(E8="",0,VALUE(LEFT(E8,1)))+IF(F8="",0,VALUE(LEFT(F8,1)))+IF(G8="",0,VALUE(LEFT(G8,1))),0)) | I8: =IF(B8="","",IF(H8<=2,"🟢 VERDE",IF(H8<=5,"🟡 AMARILLO","🔴 ROJO")))
A9: =IF(B9<>"",ROW()-4,"") | H9: =IF(B9="","",IFERROR(IF(D9="",0,VALUE(LEFT(D9,1)))+IF(E9="",0,VALUE(LEFT(E9,1)))+IF(F9="",0,VALUE(LEFT(F9,1)))+IF(G9="",0,VALUE(LEFT(G9,1))),0)) | I9: =IF(B9="","",IF(H9<=2,"🟢 VERDE",IF(H9<=5,"🟡 AMARILLO","🔴 ROJO")))
A10: =IF(B10<>"",ROW()-4,"") | H10: =IF(B10="","",IFERROR(IF(D10="",0,VALUE(LEFT(D10,1)))+IF(E10="",0,VALUE(LEFT(E10,1)))+IF(F10="",0,VALUE(LEFT(F10,1)))+IF(G10="",0,VALUE(LEFT(G10,1))),0)) | I10: =IF(B10="","",IF(H10<=2,"🟢 VERDE",IF(H10<=5,"🟡 AMARILLO","🔴 ROJO")))
A11: =IF(B11<>"",ROW()-4,"") | H11: =IF(B11="","",IFERROR(IF(D11="",0,VALUE(LEFT(D11,1)))+IF(E11="",0,VALUE(LEFT(E11,1)))+IF(F11="",0,VALUE(LEFT(F11,1)))+IF(G11="",0,VALUE(LEFT(G11,1))),0)) | I11: =IF(B11="","",IF(H11<=2,"🟢 VERDE",IF(H11<=5,"🟡 AMARILLO","🔴 ROJO")))
A12: =IF(B12<>"",ROW()-4,"") | H12: =IF(B12="","",IFERROR(IF(D12="",0,VALUE(LEFT(D12,1)))+IF(E12="",0,VALUE(LEFT(E12,1)))+IF(F12="",0,VALUE(LEFT(F12,1)))+IF(G12="",0,VALUE(LEFT(G12,1))),0)) | I12: =IF(B12="","",IF(H12<=2,"🟢 VERDE",IF(H12<=5,"🟡 AMARILLO","🔴 ROJO")))
A13: =IF(B13<>"",ROW()-4,"") | H13: =IF(B13="","",IFERROR(IF(D13="",0,VALUE(LEFT(D13,1)))+IF(E13="",0,VALUE(LEFT(E13,1)))+IF(F13="",0,VALUE(LEFT(F13,1)))+IF(G13="",0,VALUE(LEFT(G13,1))),0)) | I13: =IF(B13="","",IF(H13<=2,"🟢 VERDE",IF(H13<=5,"🟡 AMARILLO","🔴 ROJO")))
A14: =IF(B14<>"",ROW()-4,"") | H14: =IF(B14="","",IFERROR(IF(D14="",0,VALUE(LEFT(D14,1)))+IF(E14="",0,VALUE(LEFT(E14,1)))+IF(F14="",0,VALUE(LEFT(F14,1)))+IF(G14="",0,VALUE(LEFT(G14,1))),0)) | I14: =IF(B14="","",IF(H14<=2,"🟢 VERDE",IF(H14<=5,"🟡 AMARILLO","🔴 ROJO")))
A15: =IF(B15<>"",ROW()-4,"") | H15: =IF(B15="","",IFERROR(IF(D15="",0,VALUE(LEFT(D15,1)))+IF(E15="",0,VALUE(LEFT(E15,1)))+IF(F15="",0,VALUE(LEFT(F15,1)))+IF(G15="",0,VALUE(LEFT(G15,1))),0)) | I15: =IF(B15="","",IF(H15<=2,"🟢 VERDE",IF(H15<=5,"🟡 AMARILLO","🔴 ROJO")))
A16: =IF(B16<>"",ROW()-4,"") | H16: =IF(B16="","",IFERROR(IF(D16="",0,VALUE(LEFT(D16,1)))+IF(E16="",0,VALUE(LEFT(E16,1)))+IF(F16="",0,VALUE(LEFT(F16,1)))+IF(G16="",0,VALUE(LEFT(G16,1))),0)) | I16: =IF(B16="","",IF(H16<=2,"🟢 VERDE",IF(H16<=5,"🟡 AMARILLO","🔴 ROJO")))
... A54: =IF(B54<>"",ROW()-4,"") | H54: =IF(B54="","",IFERROR(IF(D54="",0,VALUE(LEFT(D54,1)))+IF(E54="",0,VALUE(LEFT(E54,1)))+IF(F54="",0,VALUE(LEFT(F54,1)))+IF(G54="",0,VALUE(LEFT(G54,1))),0)) | I54: =IF(B54="","",IF(H54<=2,"🟢 VERDE",IF(H54<=5,"🟡 AMARILLO","🔴 ROJO")))
A55: TOTALES CURSO KB | D55: =COUNTIF(D5:D54,"<>"&"") | E55: =COUNTIF(E5:E54,"<>"&"") | F55: =COUNTIF(F5:F54,"<>"&"") | G55: =COUNTIF(G5:G54,"<>"&"") | H55: =COUNTA(B5:B54) | I55: =COUNTIF(I5:I54,"🔴 ROJO")&" 🔴 "&COUNTIF(I5:I54,"🟡 AMARILLO")&" 🟡 "&COUNTIF(I5:I54,"🟢 VERDE")&" 🟢" | J55: ← Conteo: Rojo · Amarillo · Verde

Sheet KC
A1: CURSO KC — Registro de Seguimiento de Estudiantes
A2: PUNTAJES: 0 = Sin alerta / Regular 1 = Alerta leve 2 = Alerta moderada / Reiterada 3 = Alto riesgo │ SEMÁFORO: Verde 0-2 · Amarillo 3-5 · Rojo 6-12
D3: PUNTAJES POR ÁMBITO (seleccionar del menú desplegable) | H3: RESULTADO
A4: N° | B4: NOMBRE ESTUDIANTE | C4: MENTOR RESPONSABLE | D4: TRAYECTORIA EDUCATIVA | E4: ÁMBITO ACADÉMICO | F4: ÁMBITO CONDUCTUAL | G4: ÁMBITO SOCIOEMOCIONAL | H4: TOTAL | I4: SEMÁFORO | J4: OBSERVACIONES / NOTAS
A5: =IF(B5<>"",ROW()-4,"") | H5: =IF(B5="","",IFERROR(IF(D5="",0,VALUE(LEFT(D5,1)))+IF(E5="",0,VALUE(LEFT(E5,1)))+IF(F5="",0,VALUE(LEFT(F5,1)))+IF(G5="",0,VALUE(LEFT(G5,1))),0)) | I5: =IF(B5="","",IF(H5<=2,"🟢 VERDE",IF(H5<=5,"🟡 AMARILLO","🔴 ROJO")))
A6: =IF(B6<>"",ROW()-4,"") | H6: =IF(B6="","",IFERROR(IF(D6="",0,VALUE(LEFT(D6,1)))+IF(E6="",0,VALUE(LEFT(E6,1)))+IF(F6="",0,VALUE(LEFT(F6,1)))+IF(G6="",0,VALUE(LEFT(G6,1))),0)) | I6: =IF(B6="","",IF(H6<=2,"🟢 VERDE",IF(H6<=5,"🟡 AMARILLO","🔴 ROJO")))
A7: =IF(B7<>"",ROW()-4,"") | H7: =IF(B7="","",IFERROR(IF(D7="",0,VALUE(LEFT(D7,1)))+IF(E7="",0,VALUE(LEFT(E7,1)))+IF(F7="",0,VALUE(LEFT(F7,1)))+IF(G7="",0,VALUE(LEFT(G7,1))),0)) | I7: =IF(B7="","",IF(H7<=2,"🟢 VERDE",IF(H7<=5,"🟡 AMARILLO","🔴 ROJO")))
A8: =IF(B8<>"",ROW()-4,"") | H8: =IF(B8="","",IFERROR(IF(D8="",0,VALUE(LEFT(D8,1)))+IF(E8="",0,VALUE(LEFT(E8,1)))+IF(F8="",0,VALUE(LEFT(F8,1)))+IF(G8="",0,VALUE(LEFT(G8,1))),0)) | I8: =IF(B8="","",IF(H8<=2,"🟢 VERDE",IF(H8<=5,"🟡 AMARILLO","🔴 ROJO")))
A9: =IF(B9<>"",ROW()-4,"") | H9: =IF(B9="","",IFERROR(IF(D9="",0,VALUE(LEFT(D9,1)))+IF(E9="",0,VALUE(LEFT(E9,1)))+IF(F9="",0,VALUE(LEFT(F9,1)))+IF(G9="",0,VALUE(LEFT(G9,1))),0)) | I9: =IF(B9="","",IF(H9<=2,"🟢 VERDE",IF(H9<=5,"🟡 AMARILLO","🔴 ROJO")))
A10: =IF(B10<>"",ROW()-4,"") | H10: =IF(B10="","",IFERROR(IF(D10="",0,VALUE(LEFT(D10,1)))+IF(E10="",0,VALUE(LEFT(E10,1)))+IF(F10="",0,VALUE(LEFT(F10,1)))+IF(G10="",0,VALUE(LEFT(G10,1))),0)) | I10: =IF(B10="","",IF(H10<=2,"🟢 VERDE",IF(H10<=5,"🟡 AMARILLO","🔴 ROJO")))
A11: =IF(B11<>"",ROW()-4,"") | H11: =IF(B11="","",IFERROR(IF(D11="",0,VALUE(LEFT(D11,1)))+IF(E11="",0,VALUE(LEFT(E11,1)))+IF(F11="",0,VALUE(LEFT(F11,1)))+IF(G11="",0,VALUE(LEFT(G11,1))),0)) | I11: =IF(B11="","",IF(H11<=2,"🟢 VERDE",IF(H11<=5,"🟡 AMARILLO","🔴 ROJO")))
A12: =IF(B12<>"",ROW()-4,"") | H12: =IF(B12="","",IFERROR(IF(D12="",0,VALUE(LEFT(D12,1)))+IF(E12="",0,VALUE(LEFT(E12,1)))+IF(F12="",0,VALUE(LEFT(F12,1)))+IF(G12="",0,VALUE(LEFT(G12,1))),0)) | I12: =IF(B12="","",IF(H12<=2,"🟢 VERDE",IF(H12<=5,"🟡 AMARILLO","🔴 ROJO")))
A13: =IF(B13<>"",ROW()-4,"") | H13: =IF(B13="","",IFERROR(IF(D13="",0,VALUE(LEFT(D13,1)))+IF(E13="",0,VALUE(LEFT(E13,1)))+IF(F13="",0,VALUE(LEFT(F13,1)))+IF(G13="",0,VALUE(LEFT(G13,1))),0)) | I13: =IF(B13="","",IF(H13<=2,"🟢 VERDE",IF(H13<=5,"🟡 AMARILLO","🔴 ROJO")))
A14: =IF(B14<>"",ROW()-4,"") | H14: =IF(B14="","",IFERROR(IF(D14="",0,VALUE(LEFT(D14,1)))+IF(E14="",0,VALUE(LEFT(E14,1)))+IF(F14="",0,VALUE(LEFT(F14,1)))+IF(G14="",0,VALUE(LEFT(G14,1))),0)) | I14: =IF(B14="","",IF(H14<=2,"🟢 VERDE",IF(H14<=5,"🟡 AMARILLO","🔴 ROJO")))
A15: =IF(B15<>"",ROW()-4,"") | H15: =IF(B15="","",IFERROR(IF(D15="",0,VALUE(LEFT(D15,1)))+IF(E15="",0,VALUE(LEFT(E15,1)))+IF(F15="",0,VALUE(LEFT(F15,1)))+IF(G15="",0,VALUE(LEFT(G15,1))),0)) | I15: =IF(B15="","",IF(H15<=2,"🟢 VERDE",IF(H15<=5,"🟡 AMARILLO","🔴 ROJO")))
A16: =IF(B16<>"",ROW()-4,"") | H16: =IF(B16="","",IFERROR(IF(D16="",0,VALUE(LEFT(D16,1)))+IF(E16="",0,VALUE(LEFT(E16,1)))+IF(F16="",0,VALUE(LEFT(F16,1)))+IF(G16="",0,VALUE(LEFT(G16,1))),0)) | I16: =IF(B16="","",IF(H16<=2,"🟢 VERDE",IF(H16<=5,"🟡 AMARILLO","🔴 ROJO")))
... A54: =IF(B54<>"",ROW()-4,"") | H54: =IF(B54="","",IFERROR(IF(D54="",0,VALUE(LEFT(D54,1)))+IF(E54="",0,VALUE(LEFT(E54,1)))+IF(F54="",0,VALUE(LEFT(F54,1)))+IF(G54="",0,VALUE(LEFT(G54,1))),0)) | I54: =IF(B54="","",IF(H54<=2,"🟢 VERDE",IF(H54<=5,"🟡 AMARILLO","🔴 ROJO")))
A55: TOTALES CURSO KC | D55: =COUNTIF(D5:D54,"<>"&"") | E55: =COUNTIF(E5:E54,"<>"&"") | F55: =COUNTIF(F5:F54,"<>"&"") | G55: =COUNTIF(G5:G54,"<>"&"") | H55: =COUNTA(B5:B54) | I55: =COUNTIF(I5:I54,"🔴 ROJO")&" 🔴 "&COUNTIF(I5:I54,"🟡 AMARILLO")&" 🟡 "&COUNTIF(I5:I54,"🟢 VERDE")&" 🟢" | J55: ← Conteo: Rojo · Amarillo · Verde

Sheet 1A
A1: CURSO 1A — Registro de Seguimiento de Estudiantes
A2: PUNTAJES: 0 = Sin alerta / Regular 1 = Alerta leve 2 = Alerta moderada / Reiterada 3 = Alto riesgo │ SEMÁFORO: Verde 0-2 · Amarillo 3-5 · Rojo 6-12
D3: PUNTAJES POR ÁMBITO (seleccionar del menú desplegable) | H3: RESULTADO
A4: N° | B4: NOMBRE ESTUDIANTE | C4: MENTOR RESPONSABLE | D4: TRAYECTORIA EDUCATIVA | E4: ÁMBITO ACADÉMICO | F4: ÁMBITO CONDUCTUAL | G4: ÁMBITO SOCIOEMOCIONAL | H4: TOTAL | I4: SEMÁFORO | J4: OBSERVACIONES / NOTAS
A5: =IF(B5<>"",ROW()-4,"") | H5: =IF(B5="","",IFERROR(IF(D5="",0,VALUE(LEFT(D5,1)))+IF(E5="",0,VALUE(LEFT(E5,1)))+IF(F5="",0,VALUE(LEFT(F5,1)))+IF(G5="",0,VALUE(LEFT(G5,1))),0)) | I5: =IF(B5="","",IF(H5<=2,"🟢 VERDE",IF(H5<=5,"🟡 AMARILLO","🔴 ROJO")))
A6: =IF(B6<>"",ROW()-4,"") | H6: =IF(B6="","",IFERROR(IF(D6="",0,VALUE(LEFT(D6,1)))+IF(E6="",0,VALUE(LEFT(E6,1)))+IF(F6="",0,VALUE(LEFT(F6,1)))+IF(G6="",0,VALUE(LEFT(G6,1))),0)) | I6: =IF(B6="","",IF(H6<=2,"🟢 VERDE",IF(H6<=5,"🟡 AMARILLO","🔴 ROJO")))
A7: =IF(B7<>"",ROW()-4,"") | H7: =IF(B7="","",IFERROR(IF(D7="",0,VALUE(LEFT(D7,1)))+IF(E7="",0,VALUE(LEFT(E7,1)))+IF(F7="",0,VALUE(LEFT(F7,1)))+IF(G7="",0,VALUE(LEFT(G7,1))),0)) | I7: =IF(B7="","",IF(H7<=2,"🟢 VERDE",IF(H7<=5,"🟡 AMARILLO","🔴 ROJO")))
A8: =IF(B8<>"",ROW()-4,"") | H8: =IF(B8="","",IFERROR(IF(D8="",0,VALUE(LEFT(D8,1)))+IF(E8="",0,VALUE(LEFT(E8,1)))+IF(F8="",0,VALUE(LEFT(F8,1)))+IF(G8="",0,VALUE(LEFT(G8,1))),0)) | I8: =IF(B8="","",IF(H8<=2,"🟢 VERDE",IF(H8<=5,"🟡 AMARILLO","🔴 ROJO")))
A9: =IF(B9<>"",ROW()-4,"") | H9: =IF(B9="","",IFERROR(IF(D9="",0,VALUE(LEFT(D9,1)))+IF(E9="",0,VALUE(LEFT(E9,1)))+IF(F9="",0,VALUE(LEFT(F9,1)))+IF(G9="",0,VALUE(LEFT(G9,1))),0)) | I9: =IF(B9="","",IF(H9<=2,"🟢 VERDE",IF(H9<=5,"🟡 AMARILLO","🔴 ROJO")))
A10: =IF(B10<>"",ROW()-4,"") | H10: =IF(B10="","",IFERROR(IF(D10="",0,VALUE(LEFT(D10,1)))+IF(E10="",0,VALUE(LEFT(E10,1)))+IF(F10="",0,VALUE(LEFT(F10,1)))+IF(G10="",0,VALUE(LEFT(G10,1))),0)) | I10: =IF(B10="","",IF(H10<=2,"🟢 VERDE",IF(H10<=5,"🟡 AMARILLO","🔴 ROJO")))
A11: =IF(B11<>"",ROW()-4,"") | H11: =IF(B11="","",IFERROR(IF(D11="",0,VALUE(LEFT(D11,1)))+IF(E11="",0,VALUE(LEFT(E11,1)))+IF(F11="",0,VALUE(LEFT(F11,1)))+IF(G11="",0,VALUE(LEFT(G11,1))),0)) | I11: =IF(B11="","",IF(H11<=2,"🟢 VERDE",IF(H11<=5,"🟡 AMARILLO","🔴 ROJO")))
A12: =IF(B12<>"",ROW()-4,"") | H12: =IF(B12="","",IFERROR(IF(D12="",0,VALUE(LEFT(D12,1)))+IF(E12="",0,VALUE(LEFT(E12,1)))+IF(F12="",0,VALUE(LEFT(F12,1)))+IF(G12="",0,VALUE(LEFT(G12,1))),0)) | I12: =IF(B12="","",IF(H12<=2,"🟢 VERDE",IF(H12<=5,"🟡 AMARILLO","🔴 ROJO")))
A13: =IF(B13<>"",ROW()-4,"") | H13: =IF(B13="","",IFERROR(IF(D13="",0,VALUE(LEFT(D13,1)))+IF(E13="",0,VALUE(LEFT(E13,1)))+IF(F13="",0,VALUE(LEFT(F13,1)))+IF(G13="",0,VALUE(LEFT(G13,1))),0)) | I13: =IF(B13="","",IF(H13<=2,"🟢 VERDE",IF(H13<=5,"🟡 AMARILLO","🔴 ROJO")))
A14: =IF(B14<>"",ROW()-4,"") | H14: =IF(B14="","",IFERROR(IF(D14="",0,VALUE(LEFT(D14,1)))+IF(E14="",0,VALUE(LEFT(E14,1)))+IF(F14="",0,VALUE(LEFT(F14,1)))+IF(G14="",0,VALUE(LEFT(G14,1))),0)) | I14: =IF(B14="","",IF(H14<=2,"🟢 VERDE",IF(H14<=5,"🟡 AMARILLO","🔴 ROJO")))
A15: =IF(B15<>"",ROW()-4,"") | H15: =IF(B15="","",IFERROR(IF(D15="",0,VALUE(LEFT(D15,1)))+IF(E15="",0,VALUE(LEFT(E15,1)))+IF(F15="",0,VALUE(LEFT(F15,1)))+IF(G15="",0,VALUE(LEFT(G15,1))),0)) | I15: =IF(B15="","",IF(H15<=2,"🟢 VERDE",IF(H15<=5,"🟡 AMARILLO","🔴 ROJO")))
A16: =IF(B16<>"",ROW()-4,"") | H16: =IF(B16="","",IFERROR(IF(D16="",0,VALUE(LEFT(D16,1)))+IF(E16="",0,VALUE(LEFT(E16,1)))+IF(F16="",0,VALUE(LEFT(F16,1)))+IF(G16="",0,VALUE(LEFT(G16,1))),0)) | I16: =IF(B16="","",IF(H16<=2,"🟢 VERDE",IF(H16<=5,"🟡 AMARILLO","🔴 ROJO")))
... A54: =IF(B54<>"",ROW()-4,"") | H54: =IF(B54="","",IFERROR(IF(D54="",0,VALUE(LEFT(D54,1)))+IF(E54="",0,VALUE(LEFT(E54,1)))+IF(F54="",0,VALUE(LEFT(F54,1)))+IF(G54="",0,VALUE(LEFT(G54,1))),0)) | I54: =IF(B54="","",IF(H54<=2,"🟢 VERDE",IF(H54<=5,"🟡 AMARILLO","🔴 ROJO")))
A55: TOTALES CURSO 1A | D55: =COUNTIF(D5:D54,"<>"&"") | E55: =COUNTIF(E5:E54,"<>"&"") | F55: =COUNTIF(F5:F54,"<>"&"") | G55: =COUNTIF(G5:G54,"<>"&"") | H55: =COUNTA(B5:B54) | I55: =COUNTIF(I5:I54,"🔴 ROJO")&" 🔴 "&COUNTIF(I5:I54,"🟡 AMARILLO")&" 🟡 "&COUNTIF(I5:I54,"🟢 VERDE")&" 🟢" | J55: ← Conteo: Rojo · Amarillo · Verde

Sheet 1B
A1: CURSO 1B — Registro de Seguimiento de Estudiantes
A2: PUNTAJES: 0 = Sin alerta / Regular 1 = Alerta leve 2 = Alerta moderada / Reiterada 3 = Alto riesgo │ SEMÁFORO: Verde 0-2 · Amarillo 3-5 · Rojo 6-12
D3: PUNTAJES POR ÁMBITO (seleccionar del menú desplegable) | H3: RESULTADO
A4: N° | B4: NOMBRE ESTUDIANTE | C4: MENTOR RESPONSABLE | D4: TRAYECTORIA EDUCATIVA | E4: ÁMBITO ACADÉMICO | F4: ÁMBITO CONDUCTUAL | G4: ÁMBITO SOCIOEMOCIONAL | H4: TOTAL | I4: SEMÁFORO | J4: OBSERVACIONES / NOTAS
A5: =IF(B5<>"",ROW()-4,"") | H5: =IF(B5="","",IFERROR(IF(D5="",0,VALUE(LEFT(D5,1)))+IF(E5="",0,VALUE(LEFT(E5,1)))+IF(F5="",0,VALUE(LEFT(F5,1)))+IF(G5="",0,VALUE(LEFT(G5,1))),0)) | I5: =IF(B5="","",IF(H5<=2,"🟢 VERDE",IF(H5<=5,"🟡 AMARILLO","🔴 ROJO")))
A6: =IF(B6<>"",ROW()-4,"") | H6: =IF(B6="","",IFERROR(IF(D6="",0,VALUE(LEFT(D6,1)))+IF(E6="",0,VALUE(LEFT(E6,1)))+IF(F6="",0,VALUE(LEFT(F6,1)))+IF(G6="",0,VALUE(LEFT(G6,1))),0)) | I6: =IF(B6="","",IF(H6<=2,"🟢 VERDE",IF(H6<=5,"🟡 AMARILLO","🔴 ROJO")))
A7: =IF(B7<>"",ROW()-4,"") | H7: =IF(B7="","",IFERROR(IF(D7="",0,VALUE(LEFT(D7,1)))+IF(E7="",0,VALUE(LEFT(E7,1)))+IF(F7="",0,VALUE(LEFT(F7,1)))+IF(G7="",0,VALUE(LEFT(G7,1))),0)) | I7: =IF(B7="","",IF(H7<=2,"🟢 VERDE",IF(H7<=5,"🟡 AMARILLO","🔴 ROJO")))
A8: =IF(B8<>"",ROW()-4,"") | H8: =IF(B8="","",IFERROR(IF(D8="",0,VALUE(LEFT(D8,1)))+IF(E8="",0,VALUE(LEFT(E8,1)))+IF(F8="",0,VALUE(LEFT(F8,1)))+IF(G8="",0,VALUE(LEFT(G8,1))),0)) | I8: =IF(B8="","",IF(H8<=2,"🟢 VERDE",IF(H8<=5,"🟡 AMARILLO","🔴 ROJO")))
A9: =IF(B9<>"",ROW()-4,"") | H9: =IF(B9="","",IFERROR(IF(D9="",0,VALUE(LEFT(D9,1)))+IF(E9="",0,VALUE(LEFT(E9,1)))+IF(F9="",0,VALUE(LEFT(F9,1)))+IF(G9="",0,VALUE(LEFT(G9,1))),0)) | I9: =IF(B9="","",IF(H9<=2,"🟢 VERDE",IF(H9<=5,"🟡 AMARILLO","🔴 ROJO")))
A10: =IF(B10<>"",ROW()-4,"") | H10: =IF(B10="","",IFERROR(IF(D10="",0,VALUE(LEFT(D10,1)))+IF(E10="",0,VALUE(LEFT(E10,1)))+IF(F10="",0,VALUE(LEFT(F10,1)))+IF(G10="",0,VALUE(LEFT(G10,1))),0)) | I10: =IF(B10="","",IF(H10<=2,"🟢 VERDE",IF(H10<=5,"🟡 AMARILLO","🔴 ROJO")))
A11: =IF(B11<>"",ROW()-4,"") | H11: =IF(B11="","",IFERROR(IF(D11="",0,VALUE(LEFT(D11,1)))+IF(E11="",0,VALUE(LEFT(E11,1)))+IF(F11="",0,VALUE(LEFT(F11,1)))+IF(G11="",0,VALUE(LEFT(G11,1))),0)) | I11: =IF(B11="","",IF(H11<=2,"🟢 VERDE",IF(H11<=5,"🟡 AMARILLO","🔴 ROJO")))
A12: =IF(B12<>"",ROW()-4,"") | H12: =IF(B12="","",IFERROR(IF(D12="",0,VALUE(LEFT(D12,1)))+IF(E12="",0,VALUE(LEFT(E12,1)))+IF(F12="",0,VALUE(LEFT(F12,1)))+IF(G12="",0,VALUE(LEFT(G12,1))),0)) | I12: =IF(B12="","",IF(H12<=2,"🟢 VERDE",IF(H12<=5,"🟡 AMARILLO","🔴 ROJO")))
A13: =IF(B13<>"",ROW()-4,"") | H13: =IF(B13="","",IFERROR(IF(D13="",0,VALUE(LEFT(D13,1)))+IF(E13="",0,VALUE(LEFT(E13,1)))+IF(F13="",0,VALUE(LEFT(F13,1)))+IF(G13="",0,VALUE(LEFT(G13,1))),0)) | I13: =IF(B13="","",IF(H13<=2,"🟢 VERDE",IF(H13<=5,"🟡 AMARILLO","🔴 ROJO")))
A14: =IF(B14<>"",ROW()-4,"") | H14: =IF(B14="","",IFERROR(IF(D14="",0,VALUE(LEFT(D14,1)))+IF(E14="",0,VALUE(LEFT(E14,1)))+IF(F14="",0,VALUE(LEFT(F14,1)))+IF(G14="",0,VALUE(LEFT(G14,1))),0)) | I14: =IF(B14="","",IF(H14<=2,"🟢 VERDE",IF(H14<=5,"🟡 AMARILLO","🔴 ROJO")))
A15: =IF(B15<>"",ROW()-4,"") | H15: =IF(B15="","",IFERROR(IF(D15="",0,VALUE(LEFT(D15,1)))+IF(E15="",0,VALUE(LEFT(E15,1)))+IF(F15="",0,VALUE(LEFT(F15,1)))+IF(G15="",0,VALUE(LEFT(G15,1))),0)) | I15: =IF(B15="","",IF(H15<=2,"🟢 VERDE",IF(H15<=5,"🟡 AMARILLO","🔴 ROJO")))
A16: =IF(B16<>"",ROW()-4,"") | H16: =IF(B16="","",IFERROR(IF(D16="",0,VALUE(LEFT(D16,1)))+IF(E16="",0,VALUE(LEFT(E16,1)))+IF(F16="",0,VALUE(LEFT(F16,1)))+IF(G16="",0,VALUE(LEFT(G16,1))),0)) | I16: =IF(B16="","",IF(H16<=2,"🟢 VERDE",IF(H16<=5,"🟡 AMARILLO","🔴 ROJO")))
... A54: =IF(B54<>"",ROW()-4,"") | H54: =IF(B54="","",IFERROR(IF(D54="",0,VALUE(LEFT(D54,1)))+IF(E54="",0,VALUE(LEFT(E54,1)))+IF(F54="",0,VALUE(LEFT(F54,1)))+IF(G54="",0,VALUE(LEFT(G54,1))),0)) | I54: =IF(B54="","",IF(H54<=2,"🟢 VERDE",IF(H54<=5,"🟡 AMARILLO","🔴 ROJO")))
A55: TOTALES CURSO 1B | D55: =COUNTIF(D5:D54,"<>"&"") | E55: =COUNTIF(E5:E54,"<>"&"") | F55: =COUNTIF(F5:F54,"<>"&"") | G55: =COUNTIF(G5:G54,"<>"&"") | H55: =COUNTA(B5:B54) | I55: =COUNTIF(I5:I54,"🔴 ROJO")&" 🔴 "&COUNTIF(I5:I54,"🟡 AMARILLO")&" 🟡 "&COUNTIF(I5:I54,"🟢 VERDE")&" 🟢" | J55: ← Conteo: Rojo · Amarillo · Verde

Sheet 1C
A1: CURSO 1C — Registro de Seguimiento de Estudiantes
A2: PUNTAJES: 0 = Sin alerta / Regular 1 = Alerta leve 2 = Alerta moderada / Reiterada 3 = Alto riesgo │ SEMÁFORO: Verde 0-2 · Amarillo 3-5 · Rojo 6-12
D3: PUNTAJES POR ÁMBITO (seleccionar del menú desplegable) | H3: RESULTADO
A4: N° | B4: NOMBRE ESTUDIANTE | C4: MENTOR RESPONSABLE | D4: TRAYECTORIA EDUCATIVA | E4: ÁMBITO ACADÉMICO | F4: ÁMBITO CONDUCTUAL | G4: ÁMBITO SOCIOEMOCIONAL | H4: TOTAL | I4: SEMÁFORO | J4: OBSERVACIONES / NOTAS
A5: =IF(B5<>"",ROW()-4,"") | H5: =IF(B5="","",IFERROR(IF(D5="",0,VALUE(LEFT(D5,1)))+IF(E5="",0,VALUE(LEFT(E5,1)))+IF(F5="",0,VALUE(LEFT(F5,1)))+IF(G5="",0,VALUE(LEFT(G5,1))),0)) | I5: =IF(B5="","",IF(H5<=2,"🟢 VERDE",IF(H5<=5,"🟡 AMARILLO","🔴 ROJO")))
A6: =IF(B6<>"",ROW()-4,"") | H6: =IF(B6="","",IFERROR(IF(D6="",0,VALUE(LEFT(D6,1)))+IF(E6="",0,VALUE(LEFT(E6,1)))+IF(F6="",0,VALUE(LEFT(F6,1)))+IF(G6="",0,VALUE(LEFT(G6,1))),0)) | I6: =IF(B6="","",IF(H6<=2,"🟢 VERDE",IF(H6<=5,"🟡 AMARILLO","🔴 ROJO")))
A7: =IF(B7<>"",ROW()-4,"") | H7: =IF(B7="","",IFERROR(IF(D7="",0,VALUE(LEFT(D7,1)))+IF(E7="",0,VALUE(LEFT(E7,1)))+IF(F7="",0,VALUE(LEFT(F7,1)))+IF(G7="",0,VALUE(LEFT(G7,1))),0)) | I7: =IF(B7="","",IF(H7<=2,"🟢 VERDE",IF(H7<=5,"🟡 AMARILLO","🔴 ROJO")))
A8: =IF(B8<>"",ROW()-4,"") | H8: =IF(B8="","",IFERROR(IF(D8="",0,VALUE(LEFT(D8,1)))+IF(E8="",0,VALUE(LEFT(E8,1)))+IF(F8="",0,VALUE(LEFT(F8,1)))+IF(G8="",0,VALUE(LEFT(G8,1))),0)) | I8: =IF(B8="","",IF(H8<=2,"🟢 VERDE",IF(H8<=5,"🟡 AMARILLO","🔴 ROJO")))
A9: =IF(B9<>"",ROW()-4,"") | H9: =IF(B9="","",IFERROR(IF(D9="",0,VALUE(LEFT(D9,1)))+IF(E9="",0,VALUE(LEFT(E9,1)))+IF(F9="",0,VALUE(LEFT(F9,1)))+IF(G9="",0,VALUE(LEFT(G9,1))),0)) | I9: =IF(B9="","",IF(H9<=2,"🟢 VERDE",IF(H9<=5,"🟡 AMARILLO","🔴 ROJO")))
A10: =IF(B10<>"",ROW()-4,"") | H10: =IF(B10="","",IFERROR(IF(D10="",0,VALUE(LEFT(D10,1)))+IF(E10="",0,VALUE(LEFT(E10,1)))+IF(F10="",0,VALUE(LEFT(F10,1)))+IF(G10="",0,VALUE(LEFT(G10,1))),0)) | I10: =IF(B10="","",IF(H10<=2,"🟢 VERDE",IF(H10<=5,"🟡 AMARILLO","🔴 ROJO")))
A11: =IF(B11<>"",ROW()-4,"") | H11: =IF(B11="","",IFERROR(IF(D11="",0,VALUE(LEFT(D11,1)))+IF(E11="",0,VALUE(LEFT(E11,1)))+IF(F11="",0,VALUE(LEFT(F11,1)))+IF(G11="",0,VALUE(LEFT(G11,1))),0)) | I11: =IF(B11="","",IF(H11<=2,"🟢 VERDE",IF(H11<=5,"🟡 AMARILLO","🔴 ROJO")))
A12: =IF(B12<>"",ROW()-4,"") | H12: =IF(B12="","",IFERROR(IF(D12="",0,VALUE(LEFT(D12,1)))+IF(E12="",0,VALUE(LEFT(E12,1)))+IF(F12="",0,VALUE(LEFT(F12,1)))+IF(G12="",0,VALUE(LEFT(G12,1))),0)) | I12: =IF(B12="","",IF(H12<=2,"🟢 VERDE",IF(H12<=5,"🟡 AMARILLO","🔴 ROJO")))
A13: =IF(B13<>"",ROW()-4,"") | H13: =IF(B13="","",IFERROR(IF(D13="",0,VALUE(LEFT(D13,1)))+IF(E13="",0,VALUE(LEFT(E13,1)))+IF(F13="",0,VALUE(LEFT(F13,1)))+IF(G13="",0,VALUE(LEFT(G13,1))),0)) | I13: =IF(B13="","",IF(H13<=2,"🟢 VERDE",IF(H13<=5,"🟡 AMARILLO","🔴 ROJO")))
A14: =IF(B14<>"",ROW()-4,"") | H14: =IF(B14="","",IFERROR(IF(D14="",0,VALUE(LEFT(D14,1)))+IF(E14="",0,VALUE(LEFT(E14,1)))+IF(F14="",0,VALUE(LEFT(F14,1)))+IF(G14="",0,VALUE(LEFT(G14,1))),0)) | I14: =IF(B14="","",IF(H14<=2,"🟢 VERDE",IF(H14<=5,"🟡 AMARILLO","🔴 ROJO")))
A15: =IF(B15<>"",ROW()-4,"") | H15: =IF(B15="","",IFERROR(IF(D15="",0,VALUE(LEFT(D15,1)))+IF(E15="",0,VALUE(LEFT(E15,1)))+IF(F15="",0,VALUE(LEFT(F15,1)))+IF(G15="",0,VALUE(LEFT(G15,1))),0)) | I15: =IF(B15="","",IF(H15<=2,"🟢 VERDE",IF(H15<=5,"🟡 AMARILLO","🔴 ROJO")))
A16: =IF(B16<>"",ROW()-4,"") | H16: =IF(B16="","",IFERROR(IF(D16="",0,VALUE(LEFT(D16,1)))+IF(E16="",0,VALUE(LEFT(E16,1)))+IF(F16="",0,VALUE(LEFT(F16,1)))+IF(G16="",0,VALUE(LEFT(G16,1))),0)) | I16: =IF(B16="","",IF(H16<=2,"🟢 VERDE",IF(H16<=5,"🟡 AMARILLO","🔴 ROJO")))
... A54: =IF(B54<>"",ROW()-4,"") | H54: =IF(B54="","",IFERROR(IF(D54="",0,VALUE(LEFT(D54,1)))+IF(E54="",0,VALUE(LEFT(E54,1)))+IF(F54="",0,VALUE(LEFT(F54,1)))+IF(G54="",0,VALUE(LEFT(G54,1))),0)) | I54: =IF(B54="","",IF(H54<=2,"🟢 VERDE",IF(H54<=5,"🟡 AMARILLO","🔴 ROJO")))
A55: TOTALES CURSO 1C | D55: =COUNTIF(D5:D54,"<>"&"") | E55: =COUNTIF(E5:E54,"<>"&"") | F55: =COUNTIF(F5:F54,"<>"&"") | G55: =COUNTIF(G5:G54,"<>"&"") | H55: =COUNTA(B5:B54) | I55: =COUNTIF(I5:I54,"🔴 ROJO")&" 🔴 "&COUNTIF(I5:I54,"🟡 AMARILLO")&" 🟡 "&COUNTIF(I5:I54,"🟢 VERDE")&" 🟢" | J55: ← Conteo: Rojo · Amarillo · Verde

Sheet 2A
A1: CURSO 2A — Registro de Seguimiento de Estudiantes
A2: PUNTAJES: 0 = Sin alerta / Regular 1 = Alerta leve 2 = Alerta moderada / Reiterada 3 = Alto riesgo │ SEMÁFORO: Verde 0-2 · Amarillo 3-5 · Rojo 6-12
D3: PUNTAJES POR ÁMBITO (seleccionar del menú desplegable) | H3: RESULTADO
A4: N° | B4: NOMBRE ESTUDIANTE | C4: MENTOR RESPONSABLE | D4: TRAYECTORIA EDUCATIVA | E4: ÁMBITO ACADÉMICO | F4: ÁMBITO CONDUCTUAL | G4: ÁMBITO SOCIOEMOCIONAL | H4: TOTAL | I4: SEMÁFORO | J4: OBSERVACIONES / NOTAS
A5: =IF(B5<>"",ROW()-4,"") | H5: =IF(B5="","",IFERROR(IF(D5="",0,VALUE(LEFT(D5,1)))+IF(E5="",0,VALUE(LEFT(E5,1)))+IF(F5="",0,VALUE(LEFT(F5,1)))+IF(G5="",0,VALUE(LEFT(G5,1))),0)) | I5: =IF(B5="","",IF(H5<=2,"🟢 VERDE",IF(H5<=5,"🟡 AMARILLO","🔴 ROJO")))
A6: =IF(B6<>"",ROW()-4,"") | H6: =IF(B6="","",IFERROR(IF(D6="",0,VALUE(LEFT(D6,1)))+IF(E6="",0,VALUE(LEFT(E6,1)))+IF(F6="",0,VALUE(LEFT(F6,1)))+IF(G6="",0,VALUE(LEFT(G6,1))),0)) | I6: =IF(B6="","",IF(H6<=2,"🟢 VERDE",IF(H6<=5,"🟡 AMARILLO","🔴 ROJO")))
A7: =IF(B7<>"",ROW()-4,"") | H7: =IF(B7="","",IFERROR(IF(D7="",0,VALUE(LEFT(D7,1)))+IF(E7="",0,VALUE(LEFT(E7,1)))+IF(F7="",0,VALUE(LEFT(F7,1)))+IF(G7="",0,VALUE(LEFT(G7,1))),0)) | I7: =IF(B7="","",IF(H7<=2,"🟢 VERDE",IF(H7<=5,"🟡 AMARILLO","🔴 ROJO")))
A8: =IF(B8<>"",ROW()-4,"") | H8: =IF(B8="","",IFERROR(IF(D8="",0,VALUE(LEFT(D8,1)))+IF(E8="",0,VALUE(LEFT(E8,1)))+IF(F8="",0,VALUE(LEFT(F8,1)))+IF(G8="",0,VALUE(LEFT(G8,1))),0)) | I8: =IF(B8="","",IF(H8<=2,"🟢 VERDE",IF(H8<=5,"🟡 AMARILLO","🔴 ROJO")))
A9: =IF(B9<>"",ROW()-4,"") | H9: =IF(B9="","",IFERROR(IF(D9="",0,VALUE(LEFT(D9,1)))+IF(E9="",0,VALUE(LEFT(E9,1)))+IF(F9="",0,VALUE(LEFT(F9,1)))+IF(G9="",0,VALUE(LEFT(G9,1))),0)) | I9: =IF(B9="","",IF(H9<=2,"🟢 VERDE",IF(H9<=5,"🟡 AMARILLO","🔴 ROJO")))
A10: =IF(B10<>"",ROW()-4,"") | H10: =IF(B10="","",IFERROR(IF(D10="",0,VALUE(LEFT(D10,1)))+IF(E10="",0,VALUE(LEFT(E10,1)))+IF(F10="",0,VALUE(LEFT(F10,1)))+IF(G10="",0,VALUE(LEFT(G10,1))),0)) | I10: =IF(B10="","",IF(H10<=2,"🟢 VERDE",IF(H10<=5,"🟡 AMARILLO","🔴 ROJO")))
A11: =IF(B11<>"",ROW()-4,"") | H11: =IF(B11="","",IFERROR(IF(D11="",0,VALUE(LEFT(D11,1)))+IF(E11="",0,VALUE(LEFT(E11,1)))+IF(F11="",0,VALUE(LEFT(F11,1)))+IF(G11="",0,VALUE(LEFT(G11,1))),0)) | I11: =IF(B11="","",IF(H11<=2,"🟢 VERDE",IF(H11<=5,"🟡 AMARILLO","🔴 ROJO")))
A12: =IF(B12<>"",ROW()-4,"") | H12: =IF(B12="","",IFERROR(IF(D12="",0,VALUE(LEFT(D12,1)))+IF(E12="",0,VALUE(LEFT(E12,1)))+IF(F12="",0,VALUE(LEFT(F12,1)))+IF(G12="",0,VALUE(LEFT(G12,1))),0)) | I12: =IF(B12="","",IF(H12<=2,"🟢 VERDE",IF(H12<=5,"🟡 AMARILLO","🔴 ROJO")))
A13: =IF(B13<>"",ROW()-4,"") | H13: =IF(B13="","",IFERROR(IF(D13="",0,VALUE(LEFT(D13,1)))+IF(E13="",0,VALUE(LEFT(E13,1)))+IF(F13="",0,VALUE(LEFT(F13,1)))+IF(G13="",0,VALUE(LEFT(G13,1))),0)) | I13: =IF(B13="","",IF(H13<=2,"🟢 VERDE",IF(H13<=5,"🟡 AMARILLO","🔴 ROJO")))
A14: =IF(B14<>"",ROW()-4,"") | H14: =IF(B14="","",IFERROR(IF(D14="",0,VALUE(LEFT(D14,1)))+IF(E14="",0,VALUE(LEFT(E14,1)))+IF(F14="",0,VALUE(LEFT(F14,1)))+IF(G14="",0,VALUE(LEFT(G14,1))),0)) | I14: =IF(B14="","",IF(H14<=2,"🟢 VERDE",IF(H14<=5,"🟡 AMARILLO","🔴 ROJO")))
A15: =IF(B15<>"",ROW()-4,"") | H15: =IF(B15="","",IFERROR(IF(D15="",0,VALUE(LEFT(D15,1)))+IF(E15="",0,VALUE(LEFT(E15,1)))+IF(F15="",0,VALUE(LEFT(F15,1)))+IF(G15="",0,VALUE(LEFT(G15,1))),0)) | I15: =IF(B15="","",IF(H15<=2,"🟢 VERDE",IF(H15<=5,"🟡 AMARILLO","🔴 ROJO")))
A16: =IF(B16<>"",ROW()-4,"") | H16: =IF(B16="","",IFERROR(IF(D16="",0,VALUE(LEFT(D16,1)))+IF(E16="",0,VALUE(LEFT(E16,1)))+IF(F16="",0,VALUE(LEFT(F16,1)))+IF(G16="",0,VALUE(LEFT(G16,1))),0)) | I16: =IF(B16="","",IF(H16<=2,"🟢 VERDE",IF(H16<=5,"🟡 AMARILLO","🔴 ROJO")))
... A54: =IF(B54<>"",ROW()-4,"") | H54: =IF(B54="","",IFERROR(IF(D54="",0,VALUE(LEFT(D54,1)))+IF(E54="",0,VALUE(LEFT(E54,1)))+IF(F54="",0,VALUE(LEFT(F54,1)))+IF(G54="",0,VALUE(LEFT(G54,1))),0)) | I54: =IF(B54="","",IF(H54<=2,"🟢 VERDE",IF(H54<=5,"🟡 AMARILLO","🔴 ROJO")))
A55: TOTALES CURSO 2A | D55: =COUNTIF(D5:D54,"<>"&"") | E55: =COUNTIF(E5:E54,"<>"&"") | F55: =COUNTIF(F5:F54,"<>"&"") | G55: =COUNTIF(G5:G54,"<>"&"") | H55: =COUNTA(B5:B54) | I55: =COUNTIF(I5:I54,"🔴 ROJO")&" 🔴 "&COUNTIF(I5:I54,"🟡 AMARILLO")&" 🟡 "&COUNTIF(I5:I54,"🟢 VERDE")&" 🟢" | J55: ← Conteo: Rojo · Amarillo · Verde

Sheet 2B
A1: CURSO 2B — Registro de Seguimiento de Estudiantes
A2: PUNTAJES: 0 = Sin alerta / Regular 1 = Alerta leve 2 = Alerta moderada / Reiterada 3 = Alto riesgo │ SEMÁFORO: Verde 0-2 · Amarillo 3-5 · Rojo 6-12
D3: PUNTAJES POR ÁMBITO (seleccionar del menú desplegable) | H3: RESULTADO
A4: N° | B4: NOMBRE ESTUDIANTE | C4: MENTOR RESPONSABLE | D4: TRAYECTORIA EDUCATIVA | E4: ÁMBITO ACADÉMICO | F4: ÁMBITO CONDUCTUAL | G4: ÁMBITO SOCIOEMOCIONAL | H4: TOTAL | I4: SEMÁFORO | J4: OBSERVACIONES / NOTAS
A5: =IF(B5<>"",ROW()-4,"") | H5: =IF(B5="","",IFERROR(IF(D5="",0,VALUE(LEFT(D5,1)))+IF(E5="",0,VALUE(LEFT(E5,1)))+IF(F5="",0,VALUE(LEFT(F5,1)))+IF(G5="",0,VALUE(LEFT(G5,1))),0)) | I5: =IF(B5="","",IF(H5<=2,"🟢 VERDE",IF(H5<=5,"🟡 AMARILLO","🔴 ROJO")))
A6: =IF(B6<>"",ROW()-4,"") | H6: =IF(B6="","",IFERROR(IF(D6="",0,VALUE(LEFT(D6,1)))+IF(E6="",0,VALUE(LEFT(E6,1)))+IF(F6="",0,VALUE(LEFT(F6,1)))+IF(G6="",0,VALUE(LEFT(G6,1))),0)) | I6: =IF(B6="","",IF(H6<=2,"🟢 VERDE",IF(H6<=5,"🟡 AMARILLO","🔴 ROJO")))
A7: =IF(B7<>"",ROW()-4,"") | H7: =IF(B7="","",IFERROR(IF(D7="",0,VALUE(LEFT(D7,1)))+IF(E7="",0,VALUE(LEFT(E7,1)))+IF(F7="",0,VALUE(LEFT(F7,1)))+IF(G7="",0,VALUE(LEFT(G7,1))),0)) | I7: =IF(B7="","",IF(H7<=2,"🟢 VERDE",IF(H7<=5,"🟡 AMARILLO","🔴 ROJO")))
A8: =IF(B8<>"",ROW()-4,"") | H8: =IF(B8="","",IFERROR(IF(D8="",0,VALUE(LEFT(D8,1)))+IF(E8="",0,VALUE(LEFT(E8,1)))+IF(F8="",0,VALUE(LEFT(F8,1)))+IF(G8="",0,VALUE(LEFT(G8,1))),0)) | I8: =IF(B8="","",IF(H8<=2,"🟢 VERDE",IF(H8<=5,"🟡 AMARILLO","🔴 ROJO")))
A9: =IF(B9<>"",ROW()-4,"") | H9: =IF(B9="","",IFERROR(IF(D9="",0,VALUE(LEFT(D9,1)))+IF(E9="",0,VALUE(LEFT(E9,1)))+IF(F9="",0,VALUE(LEFT(F9,1)))+IF(G9="",0,VALUE(LEFT(G9,1))),0)) | I9: =IF(B9="","",IF(H9<=2,"🟢 VERDE",IF(H9<=5,"🟡 AMARILLO","🔴 ROJO")))
A10: =IF(B10<>"",ROW()-4,"") | H10: =IF(B10="","",IFERROR(IF(D10="",0,VALUE(LEFT(D10,1)))+IF(E10="",0,VALUE(LEFT(E10,1)))+IF(F10="",0,VALUE(LEFT(F10,1)))+IF(G10="",0,VALUE(LEFT(G10,1))),0)) | I10: =IF(B10="","",IF(H10<=2,"🟢 VERDE",IF(H10<=5,"🟡 AMARILLO","🔴 ROJO")))
A11: =IF(B11<>"",ROW()-4,"") | H11: =IF(B11="","",IFERROR(IF(D11="",0,VALUE(LEFT(D11,1)))+IF(E11="",0,VALUE(LEFT(E11,1)))+IF(F11="",0,VALUE(LEFT(F11,1)))+IF(G11="",0,VALUE(LEFT(G11,1))),0)) | I11: =IF(B11="","",IF(H11<=2,"🟢 VERDE",IF(H11<=5,"🟡 AMARILLO","🔴 ROJO")))
A12: =IF(B12<>"",ROW()-4,"") | H12: =IF(B12="","",IFERROR(IF(D12="",0,VALUE(LEFT(D12,1)))+IF(E12="",0,VALUE(LEFT(E12,1)))+IF(F12="",0,VALUE(LEFT(F12,1)))+IF(G12="",0,VALUE(LEFT(G12,1))),0)) | I12: =IF(B12="","",IF(H12<=2,"🟢 VERDE",IF(H12<=5,"🟡 AMARILLO","🔴 ROJO")))
A13: =IF(B13<>"",ROW()-4,"") | H13: =IF(B13="","",IFERROR(IF(D13="",0,VALUE(LEFT(D13,1)))+IF(E13="",0,VALUE(LEFT(E13,1)))+IF(F13="",0,VALUE(LEFT(F13,1)))+IF(G13="",0,VALUE(LEFT(G13,1))),0)) | I13: =IF(B13="","",IF(H13<=2,"🟢 VERDE",IF(H13<=5,"🟡 AMARILLO","🔴 ROJO")))
A14: =IF(B14<>"",ROW()-4,"") | H14: =IF(B14="","",IFERROR(IF(D14="",0,VALUE(LEFT(D14,1)))+IF(E14="",0,VALUE(LEFT(E14,1)))+IF(F14="",0,VALUE(LEFT(F14,1)))+IF(G14="",0,VALUE(LEFT(G14,1))),0)) | I14: =IF(B14="","",IF(H14<=2,"🟢 VERDE",IF(H14<=5,"🟡 AMARILLO","🔴 ROJO")))
A15: =IF(B15<>"",ROW()-4,"") | H15: =IF(B15="","",IFERROR(IF(D15="",0,VALUE(LEFT(D15,1)))+IF(E15="",0,VALUE(LEFT(E15,1)))+IF(F15="",0,VALUE(LEFT(F15,1)))+IF(G15="",0,VALUE(LEFT(G15,1))),0)) | I15: =IF(B15="","",IF(H15<=2,"🟢 VERDE",IF(H15<=5,"🟡 AMARILLO","🔴 ROJO")))
A16: =IF(B16<>"",ROW()-4,"") | H16: =IF(B16="","",IFERROR(IF(D16="",0,VALUE(LEFT(D16,1)))+IF(E16="",0,VALUE(LEFT(E16,1)))+IF(F16="",0,VALUE(LEFT(F16,1)))+IF(G16="",0,VALUE(LEFT(G16,1))),0)) | I16: =IF(B16="","",IF(H16<=2,"🟢 VERDE",IF(H16<=5,"🟡 AMARILLO","🔴 ROJO")))
... A54: =IF(B54<>"",ROW()-4,"") | H54: =IF(B54="","",IFERROR(IF(D54="",0,VALUE(LEFT(D54,1)))+IF(E54="",0,VALUE(LEFT(E54,1)))+IF(F54="",0,VALUE(LEFT(F54,1)))+IF(G54="",0,VALUE(LEFT(G54,1))),0)) | I54: =IF(B54="","",IF(H54<=2,"🟢 VERDE",IF(H54<=5,"🟡 AMARILLO","🔴 ROJO")))
A55: TOTALES CURSO 2B | D55: =COUNTIF(D5:D54,"<>"&"") | E55: =COUNTIF(E5:E54,"<>"&"") | F55: =COUNTIF(F5:F54,"<>"&"") | G55: =COUNTIF(G5:G54,"<>"&"") | H55: =COUNTA(B5:B54) | I55: =COUNTIF(I5:I54,"🔴 ROJO")&" 🔴 "&COUNTIF(I5:I54,"🟡 AMARILLO")&" 🟡 "&COUNTIF(I5:I54,"🟢 VERDE")&" 🟢" | J55: ← Conteo: Rojo · Amarillo · Verde

Sheet 2C
A1: CURSO 2C — Registro de Seguimiento de Estudiantes
A2: PUNTAJES: 0 = Sin alerta / Regular 1 = Alerta leve 2 = Alerta moderada / Reiterada 3 = Alto riesgo │ SEMÁFORO: Verde 0-2 · Amarillo 3-5 · Rojo 6-12
D3: PUNTAJES POR ÁMBITO (seleccionar del menú desplegable) | H3: RESULTADO
A4: N° | B4: NOMBRE ESTUDIANTE | C4: MENTOR RESPONSABLE | D4: TRAYECTORIA EDUCATIVA | E4: ÁMBITO ACADÉMICO | F4: ÁMBITO CONDUCTUAL | G4: ÁMBITO SOCIOEMOCIONAL | H4: TOTAL | I4: SEMÁFORO | J4: OBSERVACIONES / NOTAS
A5: =IF(B5<>"",ROW()-4,"") | H5: =IF(B5="","",IFERROR(IF(D5="",0,VALUE(LEFT(D5,1)))+IF(E5="",0,VALUE(LEFT(E5,1)))+IF(F5="",0,VALUE(LEFT(F5,1)))+IF(G5="",0,VALUE(LEFT(G5,1))),0)) | I5: =IF(B5="","",IF(H5<=2,"🟢 VERDE",IF(H5<=5,"🟡 AMARILLO","🔴 ROJO")))
A6: =IF(B6<>"",ROW()-4,"") | H6: =IF(B6="","",IFERROR(IF(D6="",0,VALUE(LEFT(D6,1)))+IF(E6="",0,VALUE(LEFT(E6,1)))+IF(F6="",0,VALUE(LEFT(F6,1)))+IF(G6="",0,VALUE(LEFT(G6,1))),0)) | I6: =IF(B6="","",IF(H6<=2,"🟢 VERDE",IF(H6<=5,"🟡 AMARILLO","🔴 ROJO")))
A7: =IF(B7<>"",ROW()-4,"") | H7: =IF(B7="","",IFERROR(IF(D7="",0,VALUE(LEFT(D7,1)))+IF(E7="",0,VALUE(LEFT(E7,1)))+IF(F7="",0,VALUE(LEFT(F7,1)))+IF(G7="",0,VALUE(LEFT(G7,1))),0)) | I7: =IF(B7="","",IF(H7<=2,"🟢 VERDE",IF(H7<=5,"🟡 AMARILLO","🔴 ROJO")))
A8: =IF(B8<>"",ROW()-4,"") | H8: =IF(B8="","",IFERROR(IF(D8="",0,VALUE(LEFT(D8,1)))+IF(E8="",0,VALUE(LEFT(E8,1)))+IF(F8="",0,VALUE(LEFT(F8,1)))+IF(G8="",0,VALUE(LEFT(G8,1))),0)) | I8: =IF(B8="","",IF(H8<=2,"🟢 VERDE",IF(H8<=5,"🟡 AMARILLO","🔴 ROJO")))
A9: =IF(B9<>"",ROW()-4,"") | H9: =IF(B9="","",IFERROR(IF(D9="",0,VALUE(LEFT(D9,1)))+IF(E9="",0,VALUE(LEFT(E9,1)))+IF(F9="",0,VALUE(LEFT(F9,1)))+IF(G9="",0,VALUE(LEFT(G9,1))),0)) | I9: =IF(B9="","",IF(H9<=2,"🟢 VERDE",IF(H9<=5,"🟡 AMARILLO","🔴 ROJO")))
A10: =IF(B10<>"",ROW()-4,"") | H10: =IF(B10="","",IFERROR(IF(D10="",0,VALUE(LEFT(D10,1)))+IF(E10="",0,VALUE(LEFT(E10,1)))+IF(F10="",0,VALUE(LEFT(F10,1)))+IF(G10="",0,VALUE(LEFT(G10,1))),0)) | I10: =IF(B10="","",IF(H10<=2,"🟢 VERDE",IF(H10<=5,"🟡 AMARILLO","🔴 ROJO")))
A11: =IF(B11<>"",ROW()-4,"") | H11: =IF(B11="","",IFERROR(IF(D11="",0,VALUE(LEFT(D11,1)))+IF(E11="",0,VALUE(LEFT(E11,1)))+IF(F11="",0,VALUE(LEFT(F11,1)))+IF(G11="",0,VALUE(LEFT(G11,1))),0)) | I11: =IF(B11="","",IF(H11<=2,"🟢 VERDE",IF(H11<=5,"🟡 AMARILLO","🔴 ROJO")))
A12: =IF(B12<>"",ROW()-4,"") | H12: =IF(B12="","",IFERROR(IF(D12="",0,VALUE(LEFT(D12,1)))+IF(E12="",0,VALUE(LEFT(E12,1)))+IF(F12="",0,VALUE(LEFT(F12,1)))+IF(G12="",0,VALUE(LEFT(G12,1))),0)) | I12: =IF(B12="","",IF(H12<=2,"🟢 VERDE",IF(H12<=5,"🟡 AMARILLO","🔴 ROJO")))
A13: =IF(B13<>"",ROW()-4,"") | H13: =IF(B13="","",IFERROR(IF(D13="",0,VALUE(LEFT(D13,1)))+IF(E13="",0,VALUE(LEFT(E13,1)))+IF(F13="",0,VALUE(LEFT(F13,1)))+IF(G13="",0,VALUE(LEFT(G13,1))),0)) | I13: =IF(B13="","",IF(H13<=2,"🟢 VERDE",IF(H13<=5,"🟡 AMARILLO","🔴 ROJO")))
A14: =IF(B14<>"",ROW()-4,"") | H14: =IF(B14="","",IFERROR(IF(D14="",0,VALUE(LEFT(D14,1)))+IF(E14="",0,VALUE(LEFT(E14,1)))+IF(F14="",0,VALUE(LEFT(F14,1)))+IF(G14="",0,VALUE(LEFT(G14,1))),0)) | I14: =IF(B14="","",IF(H14<=2,"🟢 VERDE",IF(H14<=5,"🟡 AMARILLO","🔴 ROJO")))
A15: =IF(B15<>"",ROW()-4,"") | H15: =IF(B15="","",IFERROR(IF(D15="",0,VALUE(LEFT(D15,1)))+IF(E15="",0,VALUE(LEFT(E15,1)))+IF(F15="",0,VALUE(LEFT(F15,1)))+IF(G15="",0,VALUE(LEFT(G15,1))),0)) | I15: =IF(B15="","",IF(H15<=2,"🟢 VERDE",IF(H15<=5,"🟡 AMARILLO","🔴 ROJO")))
A16: =IF(B16<>"",ROW()-4,"") | H16: =IF(B16="","",IFERROR(IF(D16="",0,VALUE(LEFT(D16,1)))+IF(E16="",0,VALUE(LEFT(E16,1)))+IF(F16="",0,VALUE(LEFT(F16,1)))+IF(G16="",0,VALUE(LEFT(G16,1))),0)) | I16: =IF(B16="","",IF(H16<=2,"🟢 VERDE",IF(H16<=5,"🟡 AMARILLO","🔴 ROJO")))
... A54: =IF(B54<>"",ROW()-4,"") | H54: =IF(B54="","",IFERROR(IF(D54="",0,VALUE(LEFT(D54,1)))+IF(E54="",0,VALUE(LEFT(E54,1)))+IF(F54="",0,VALUE(LEFT(F54,1)))+IF(G54="",0,VALUE(LEFT(G54,1))),0)) | I54: =IF(B54="","",IF(H54<=2,"🟢 VERDE",IF(H54<=5,"🟡 AMARILLO","🔴 ROJO")))
A55: TOTALES CURSO 2C | D55: =COUNTIF(D5:D54,"<>"&"") | E55: =COUNTIF(E5:E54,"<>"&"") | F55: =COUNTIF(F5:F54,"<>"&"") | G55: =COUNTIF(G5:G54,"<>"&"") | H55: =COUNTA(B5:B54) | I55: =COUNTIF(I5:I54,"🔴 ROJO")&" 🔴 "&COUNTIF(I5:I54,"🟡 AMARILLO")&" 🟡 "&COUNTIF(I5:I54,"🟢 VERDE")&" 🟢" | J55: ← Conteo: Rojo · Amarillo · Verde

Sheet 3A
A1: CURSO 3A — Registro de Seguimiento de Estudiantes
A2: PUNTAJES: 0 = Sin alerta / Regular 1 = Alerta leve 2 = Alerta moderada / Reiterada 3 = Alto riesgo │ SEMÁFORO: Verde 0-2 · Amarillo 3-5 · Rojo 6-12
D3: PUNTAJES POR ÁMBITO (seleccionar del menú desplegable) | H3: RESULTADO
A4: N° | B4: NOMBRE ESTUDIANTE | C4: MENTOR RESPONSABLE | D4: TRAYECTORIA EDUCATIVA | E4: ÁMBITO ACADÉMICO | F4: ÁMBITO CONDUCTUAL | G4: ÁMBITO SOCIOEMOCIONAL | H4: TOTAL | I4: SEMÁFORO | J4: OBSERVACIONES / NOTAS
A5: =IF(B5<>"",ROW()-4,"") | H5: =IF(B5="","",IFERROR(IF(D5="",0,VALUE(LEFT(D5,1)))+IF(E5="",0,VALUE(LEFT(E5,1)))+IF(F5="",0,VALUE(LEFT(F5,1)))+IF(G5="",0,VALUE(LEFT(G5,1))),0)) | I5: =IF(B5="","",IF(H5<=2,"🟢 VERDE",IF(H5<=5,"🟡 AMARILLO","🔴 ROJO")))
A6: =IF(B6<>"",ROW()-4,"") | H6: =IF(B6="","",IFERROR(IF(D6="",0,VALUE(LEFT(D6,1)))+IF(E6="",0,VALUE(LEFT(E6,1)))+IF(F6="",0,VALUE(LEFT(F6,1)))+IF(G6="",0,VALUE(LEFT(G6,1))),0)) | I6: =IF(B6="","",IF(H6<=2,"🟢 VERDE",IF(H6<=5,"🟡 AMARILLO","🔴 ROJO")))
A7: =IF(B7<>"",ROW()-4,"") | H7: =IF(B7="","",IFERROR(IF(D7="",0,VALUE(LEFT(D7,1)))+IF(E7="",0,VALUE(LEFT(E7,1)))+IF(F7="",0,VALUE(LEFT(F7,1)))+IF(G7="",0,VALUE(LEFT(G7,1))),0)) | I7: =IF(B7="","",IF(H7<=2,"🟢 VERDE",IF(H7<=5,"🟡 AMARILLO","🔴 ROJO")))
A8: =IF(B8<>"",ROW()-4,"") | H8: =IF(B8="","",IFERROR(IF(D8="",0,VALUE(LEFT(D8,1)))+IF(E8="",0,VALUE(LEFT(E8,1)))+IF(F8="",0,VALUE(LEFT(F8,1)))+IF(G8="",0,VALUE(LEFT(G8,1))),0)) | I8: =IF(B8="","",IF(H8<=2,"🟢 VERDE",IF(H8<=5,"🟡 AMARILLO","🔴 ROJO")))
A9: =IF(B9<>"",ROW()-4,"") | H9: =IF(B9="","",IFERROR(IF(D9="",0,VALUE(LEFT(D9,1)))+IF(E9="",0,VALUE(LEFT(E9,1)))+IF(F9="",0,VALUE(LEFT(F9,1)))+IF(G9="",0,VALUE(LEFT(G9,1))),0)) | I9: =IF(B9="","",IF(H9<=2,"🟢 VERDE",IF(H9<=5,"🟡 AMARILLO","🔴 ROJO")))
A10: =IF(B10<>"",ROW()-4,"") | H10: =IF(B10="","",IFERROR(IF(D10="",0,VALUE(LEFT(D10,1)))+IF(E10="",0,VALUE(LEFT(E10,1)))+IF(F10="",0,VALUE(LEFT(F10,1)))+IF(G10="",0,VALUE(LEFT(G10,1))),0)) | I10: =IF(B10="","",IF(H10<=2,"🟢 VERDE",IF(H10<=5,"🟡 AMARILLO","🔴 ROJO")))
A11: =IF(B11<>"",ROW()-4,"") | H11: =IF(B11="","",IFERROR(IF(D11="",0,VALUE(LEFT(D11,1)))+IF(E11="",0,VALUE(LEFT(E11,1)))+IF(F11="",0,VALUE(LEFT(F11,1)))+IF(G11="",0,VALUE(LEFT(G11,1))),0)) | I11: =IF(B11="","",IF(H11<=2,"🟢 VERDE",IF(H11<=5,"🟡 AMARILLO","🔴 ROJO")))
A12: =IF(B12<>"",ROW()-4,"") | H12: =IF(B12="","",IFERROR(IF(D12="",0,VALUE(LEFT(D12,1)))+IF(E12="",0,VALUE(LEFT(E12,1)))+IF(F12="",0,VALUE(LEFT(F12,1)))+IF(G12="",0,VALUE(LEFT(G12,1))),0)) | I12: =IF(B12="","",IF(H12<=2,"🟢 VERDE",IF(H12<=5,"🟡 AMARILLO","🔴 ROJO")))
A13: =IF(B13<>"",ROW()-4,"") | H13: =IF(B13="","",IFERROR(IF(D13="",0,VALUE(LEFT(D13,1)))+IF(E13="",0,VALUE(LEFT(E13,1)))+IF(F13="",0,VALUE(LEFT(F13,1)))+IF(G13="",0,VALUE(LEFT(G13,1))),0)) | I13: =IF(B13="","",IF(H13<=2,"🟢 VERDE",IF(H13<=5,"🟡 AMARILLO","🔴 ROJO")))
A14: =IF(B14<>"",ROW()-4,"") | H14: =IF(B14="","",IFERROR(IF(D14="",0,VALUE(LEFT(D14,1)))+IF(E14="",0,VALUE(LEFT(E14,1)))+IF(F14="",0,VALUE(LEFT(F14,1)))+IF(G14="",0,VALUE(LEFT(G14,1))),0)) | I14: =IF(B14="","",IF(H14<=2,"🟢 VERDE",IF(H14<=5,"🟡 AMARILLO","🔴 ROJO")))
A15: =IF(B15<>"",ROW()-4,"") | H15: =IF(B15="","",IFERROR(IF(D15="",0,VALUE(LEFT(D15,1)))+IF(E15="",0,VALUE(LEFT(E15,1)))+IF(F15="",0,VALUE(LEFT(F15,1)))+IF(G15="",0,VALUE(LEFT(G15,1))),0)) | I15: =IF(B15="","",IF(H15<=2,"🟢 VERDE",IF(H15<=5,"🟡 AMARILLO","🔴 ROJO")))
A16: =IF(B16<>"",ROW()-4,"") | H16: =IF(B16="","",IFERROR(IF(D16="",0,VALUE(LEFT(D16,1)))+IF(E16="",0,VALUE(LEFT(E16,1)))+IF(F16="",0,VALUE(LEFT(F16,1)))+IF(G16="",0,VALUE(LEFT(G16,1))),0)) | I16: =IF(B16="","",IF(H16<=2,"🟢 VERDE",IF(H16<=5,"🟡 AMARILLO","🔴 ROJO")))
... A54: =IF(B54<>"",ROW()-4,"") | H54: =IF(B54="","",IFERROR(IF(D54="",0,VALUE(LEFT(D54,1)))+IF(E54="",0,VALUE(LEFT(E54,1)))+IF(F54="",0,VALUE(LEFT(F54,1)))+IF(G54="",0,VALUE(LEFT(G54,1))),0)) | I54: =IF(B54="","",IF(H54<=2,"🟢 VERDE",IF(H54<=5,"🟡 AMARILLO","🔴 ROJO")))
A55: TOTALES CURSO 3A | D55: =COUNTIF(D5:D54,"<>"&"") | E55: =COUNTIF(E5:E54,"<>"&"") | F55: =COUNTIF(F5:F54,"<>"&"") | G55: =COUNTIF(G5:G54,"<>"&"") | H55: =COUNTA(B5:B54) | I55: =COUNTIF(I5:I54,"🔴 ROJO")&" 🔴 "&COUNTIF(I5:I54,"🟡 AMARILLO")&" 🟡 "&COUNTIF(I5:I54,"🟢 VERDE")&" 🟢" | J55: ← Conteo: Rojo · Amarillo · Verde

Sheet 3B
A1: CURSO 3B — Registro de Seguimiento de Estudiantes
A2: PUNTAJES: 0 = Sin alerta / Regular 1 = Alerta leve 2 = Alerta moderada / Reiterada 3 = Alto riesgo │ SEMÁFORO: Verde 0-2 · Amarillo 3-5 · Rojo 6-12
D3: PUNTAJES POR ÁMBITO (seleccionar del menú desplegable) | H3: RESULTADO
A4: N° | B4: NOMBRE ESTUDIANTE | C4: MENTOR RESPONSABLE | D4: TRAYECTORIA EDUCATIVA | E4: ÁMBITO ACADÉMICO | F4: ÁMBITO CONDUCTUAL | G4: ÁMBITO SOCIOEMOCIONAL | H4: TOTAL | I4: SEMÁFORO | J4: OBSERVACIONES / NOTAS
A5: =IF(B5<>"",ROW()-4,"") | H5: =IF(B5="","",IFERROR(IF(D5="",0,VALUE(LEFT(D5,1)))+IF(E5="",0,VALUE(LEFT(E5,1)))+IF(F5="",0,VALUE(LEFT(F5,1)))+IF(G5="",0,VALUE(LEFT(G5,1))),0)) | I5: =IF(B5="","",IF(H5<=2,"🟢 VERDE",IF(H5<=5,"🟡 AMARILLO","🔴 ROJO")))
A6: =IF(B6<>"",ROW()-4,"") | H6: =IF(B6="","",IFERROR(IF(D6="",0,VALUE(LEFT(D6,1)))+IF(E6="",0,VALUE(LEFT(E6,1)))+IF(F6="",0,VALUE(LEFT(F6,1)))+IF(G6="",0,VALUE(LEFT(G6,1))),0)) | I6: =IF(B6="","",IF(H6<=2,"🟢 VERDE",IF(H6<=5,"🟡 AMARILLO","🔴 ROJO")))
A7: =IF(B7<>"",ROW()-4,"") | H7: =IF(B7="","",IFERROR(IF(D7="",0,VALUE(LEFT(D7,1)))+IF(E7="",0,VALUE(LEFT(E7,1)))+IF(F7="",0,VALUE(LEFT(F7,1)))+IF(G7="",0,VALUE(LEFT(G7,1))),0)) | I7: =IF(B7="","",IF(H7<=2,"🟢 VERDE",IF(H7<=5,"🟡 AMARILLO","🔴 ROJO")))
A8: =IF(B8<>"",ROW()-4,"") | H8: =IF(B8="","",IFERROR(IF(D8="",0,VALUE(LEFT(D8,1)))+IF(E8="",0,VALUE(LEFT(E8,1)))+IF(F8="",0,VALUE(LEFT(F8,1)))+IF(G8="",0,VALUE(LEFT(G8,1))),0)) | I8: =IF(B8="","",IF(H8<=2,"🟢 VERDE",IF(H8<=5,"🟡 AMARILLO","🔴 ROJO")))
A9: =IF(B9<>"",ROW()-4,"") | H9: =IF(B9="","",IFERROR(IF(D9="",0,VALUE(LEFT(D9,1)))+IF(E9="",0,VALUE(LEFT(E9,1)))+IF(F9="",0,VALUE(LEFT(F9,1)))+IF(G9="",0,VALUE(LEFT(G9,1))),0)) | I9: =IF(B9="","",IF(H9<=2,"🟢 VERDE",IF(H9<=5,"🟡 AMARILLO","🔴 ROJO")))
A10: =IF(B10<>"",ROW()-4,"") | H10: =IF(B10="","",IFERROR(IF(D10="",0,VALUE(LEFT(D10,1)))+IF(E10="",0,VALUE(LEFT(E10,1)))+IF(F10="",0,VALUE(LEFT(F10,1)))+IF(G10="",0,VALUE(LEFT(G10,1))),0)) | I10: =IF(B10="","",IF(H10<=2,"🟢 VERDE",IF(H10<=5,"🟡 AMARILLO","🔴 ROJO")))
A11: =IF(B11<>"",ROW()-4,"") | H11: =IF(B11="","",IFERROR(IF(D11="",0,VALUE(LEFT(D11,1)))+IF(E11="",0,VALUE(LEFT(E11,1)))+IF(F11="",0,VALUE(LEFT(F11,1)))+IF(G11="",0,VALUE(LEFT(G11,1))),0)) | I11: =IF(B11="","",IF(H11<=2,"🟢 VERDE",IF(H11<=5,"🟡 AMARILLO","🔴 ROJO")))
A12: =IF(B12<>"",ROW()-4,"") | H12: =IF(B12="","",IFERROR(IF(D12="",0,VALUE(LEFT(D12,1)))+IF(E12="",0,VALUE(LEFT(E12,1)))+IF(F12="",0,VALUE(LEFT(F12,1)))+IF(G12="",0,VALUE(LEFT(G12,1))),0)) | I12: =IF(B12="","",IF(H12<=2,"🟢 VERDE",IF(H12<=5,"🟡 AMARILLO","🔴 ROJO")))
A13: =IF(B13<>"",ROW()-4,"") | H13: =IF(B13="","",IFERROR(IF(D13="",0,VALUE(LEFT(D13,1)))+IF(E13="",0,VALUE(LEFT(E13,1)))+IF(F13="",0,VALUE(LEFT(F13,1)))+IF(G13="",0,VALUE(LEFT(G13,1))),0)) | I13: =IF(B13="","",IF(H13<=2,"🟢 VERDE",IF(H13<=5,"🟡 AMARILLO","🔴 ROJO")))
A14: =IF(B14<>"",ROW()-4,"") | H14: =IF(B14="","",IFERROR(IF(D14="",0,VALUE(LEFT(D14,1)))+IF(E14="",0,VALUE(LEFT(E14,1)))+IF(F14="",0,VALUE(LEFT(F14,1)))+IF(G14="",0,VALUE(LEFT(G14,1))),0)) | I14: =IF(B14="","",IF(H14<=2,"🟢 VERDE",IF(H14<=5,"🟡 AMARILLO","🔴 ROJO")))
A15: =IF(B15<>"",ROW()-4,"") | H15: =IF(B15="","",IFERROR(IF(D15="",0,VALUE(LEFT(D15,1)))+IF(E15="",0,VALUE(LEFT(E15,1)))+IF(F15="",0,VALUE(LEFT(F15,1)))+IF(G15="",0,VALUE(LEFT(G15,1))),0)) | I15: =IF(B15="","",IF(H15<=2,"🟢 VERDE",IF(H15<=5,"🟡 AMARILLO","🔴 ROJO")))
